[2023-12-20T08:19:51.745+0000] {taskinstance.py:1957} INFO - Dependencies all met for dep_context=non-requeueable deps ti=<TaskInstance: our_dag_with_python_operator_v04.greet manual__2023-12-20T08:19:45.835184+00:00 [queued]>
[2023-12-20T08:19:51.781+0000] {taskinstance.py:1957} INFO - Dependencies all met for dep_context=requeueable deps ti=<TaskInstance: our_dag_with_python_operator_v04.greet manual__2023-12-20T08:19:45.835184+00:00 [queued]>
[2023-12-20T08:19:51.789+0000] {taskinstance.py:2171} INFO - Starting attempt 1 of 1
[2023-12-20T08:19:51.859+0000] {taskinstance.py:2192} INFO - Executing <Task(PythonOperator): greet> on 2023-12-20 08:19:45.835184+00:00
[2023-12-20T08:19:51.886+0000] {standard_task_runner.py:60} INFO - Started process 5366 to run task
[2023-12-20T08:19:51.915+0000] {standard_task_runner.py:87} INFO - Running: ['***', 'tasks', 'run', 'our_dag_with_python_operator_v04', 'greet', 'manual__2023-12-20T08:19:45.835184+00:00', '--job-id', '27', '--raw', '--subdir', 'DAGS_FOLDER/create_dag_with_python_operator.py', '--cfg-path', '/tmp/tmpbz_5xts4']
[2023-12-20T08:19:51.927+0000] {standard_task_runner.py:88} INFO - Job 27: Subtask greet
[2023-12-20T08:19:52.070+0000] {task_command.py:423} INFO - Running <TaskInstance: our_dag_with_python_operator_v04.greet manual__2023-12-20T08:19:45.835184+00:00 [running]> on host 5bd5db5a939a
[2023-12-20T08:19:52.290+0000] {taskinstance.py:2481} INFO - Exporting env vars: AIRFLOW_CTX_DAG_OWNER='sarwar' AIRFLOW_CTX_DAG_ID='our_dag_with_python_operator_v04' AIRFLOW_CTX_TASK_ID='greet' AIRFLOW_CTX_EXECUTION_DATE='2023-12-20T08:19:45.835184+00:00' AIRFLOW_CTX_TRY_NUMBER='1' AIRFLOW_CTX_DAG_RUN_ID='manual__2023-12-20T08:19:45.835184+00:00'
[2023-12-20T08:19:52.297+0000] {taskinstance.py:2699} ERROR - Task failed with exception
Traceback (most recent call last):
  File "/home/airflow/.local/lib/python3.8/site-packages/airflow/models/taskinstance.py", line 433, in _execute_task
    result = execute_callable(context=context, **execute_callable_kwargs)
  File "/home/airflow/.local/lib/python3.8/site-packages/airflow/operators/python.py", line 199, in execute
    return_value = self.execute_callable()
  File "/home/airflow/.local/lib/python3.8/site-packages/airflow/operators/python.py", line 216, in execute_callable
    return self.python_callable(*self.op_args, **self.op_kwargs)
  File "/opt/airflow/dags/create_dag_with_python_operator.py", line 12, in greet
    name = ti.xcoms_pull(task_ids='get_name')
AttributeError: 'TaskInstance' object has no attribute 'xcoms_pull'
[2023-12-20T08:19:52.344+0000] {taskinstance.py:1138} INFO - Marking task as FAILED. dag_id=our_dag_with_python_operator_v04, task_id=greet, execution_date=20231220T081945, start_date=20231220T081951, end_date=20231220T081952
[2023-12-20T08:19:52.388+0000] {standard_task_runner.py:107} ERROR - Failed to execute job 27 for task greet ('TaskInstance' object has no attribute 'xcoms_pull'; 5366)
[2023-12-20T08:19:52.441+0000] {local_task_job_runner.py:234} INFO - Task exited with return code 1
[2023-12-20T08:19:52.483+0000] {taskinstance.py:3281} INFO - 0 downstream tasks scheduled from follow-on schedule check
