[2023-12-21T17:55:51.612+0000] {processor.py:161} INFO - Started process (PID=2991) to work on /opt/airflow/dags/dag_with_postgres_operator.py
[2023-12-21T17:55:51.622+0000] {processor.py:830} INFO - Processing file /opt/airflow/dags/dag_with_postgres_operator.py for tasks to queue
[2023-12-21T17:55:51.629+0000] {logging_mixin.py:188} INFO - [2023-12-21T17:55:51.628+0000] {dagbag.py:538} INFO - Filling up the DagBag from /opt/airflow/dags/dag_with_postgres_operator.py
[2023-12-21T17:55:51.670+0000] {processor.py:842} WARNING - No viable dags retrieved from /opt/airflow/dags/dag_with_postgres_operator.py
[2023-12-21T17:55:51.706+0000] {processor.py:183} INFO - Processing /opt/airflow/dags/dag_with_postgres_operator.py took 0.106 seconds
[2023-12-21T17:56:22.326+0000] {processor.py:161} INFO - Started process (PID=3028) to work on /opt/airflow/dags/dag_with_postgres_operator.py
[2023-12-21T17:56:22.333+0000] {processor.py:830} INFO - Processing file /opt/airflow/dags/dag_with_postgres_operator.py for tasks to queue
[2023-12-21T17:56:22.338+0000] {logging_mixin.py:188} INFO - [2023-12-21T17:56:22.336+0000] {dagbag.py:538} INFO - Filling up the DagBag from /opt/airflow/dags/dag_with_postgres_operator.py
[2023-12-21T17:56:22.431+0000] {processor.py:842} WARNING - No viable dags retrieved from /opt/airflow/dags/dag_with_postgres_operator.py
[2023-12-21T17:56:22.542+0000] {processor.py:183} INFO - Processing /opt/airflow/dags/dag_with_postgres_operator.py took 0.250 seconds
[2023-12-21T17:56:32.516+0000] {processor.py:161} INFO - Started process (PID=3057) to work on /opt/airflow/dags/dag_with_postgres_operator.py
[2023-12-21T17:56:32.552+0000] {processor.py:830} INFO - Processing file /opt/airflow/dags/dag_with_postgres_operator.py for tasks to queue
[2023-12-21T17:56:32.559+0000] {logging_mixin.py:188} INFO - [2023-12-21T17:56:32.558+0000] {dagbag.py:538} INFO - Filling up the DagBag from /opt/airflow/dags/dag_with_postgres_operator.py
[2023-12-21T17:56:33.288+0000] {logging_mixin.py:188} INFO - [2023-12-21T17:56:33.103+0000] {dagbag.py:348} ERROR - Failed to import: /opt/airflow/dags/dag_with_postgres_operator.py
Traceback (most recent call last):
  File "/home/airflow/.local/lib/python3.8/site-packages/airflow/models/dagbag.py", line 344, in parse
    loader.exec_module(new_module)
  File "<frozen importlib._bootstrap_external>", line 843, in exec_module
  File "<frozen importlib._bootstrap>", line 219, in _call_with_frames_removed
  File "/opt/airflow/dags/dag_with_postgres_operator.py", line 20, in <module>
    task1 = BashOperator(
NameError: name 'BashOperator' is not defined
[2023-12-21T17:56:33.307+0000] {processor.py:842} WARNING - No viable dags retrieved from /opt/airflow/dags/dag_with_postgres_operator.py
[2023-12-21T17:56:34.639+0000] {processor.py:183} INFO - Processing /opt/airflow/dags/dag_with_postgres_operator.py took 2.143 seconds
[2023-12-21T17:57:05.249+0000] {processor.py:161} INFO - Started process (PID=3095) to work on /opt/airflow/dags/dag_with_postgres_operator.py
[2023-12-21T17:57:05.267+0000] {processor.py:830} INFO - Processing file /opt/airflow/dags/dag_with_postgres_operator.py for tasks to queue
[2023-12-21T17:57:05.273+0000] {logging_mixin.py:188} INFO - [2023-12-21T17:57:05.272+0000] {dagbag.py:538} INFO - Filling up the DagBag from /opt/airflow/dags/dag_with_postgres_operator.py
[2023-12-21T17:57:05.982+0000] {logging_mixin.py:188} INFO - [2023-12-21T17:57:05.931+0000] {dagbag.py:348} ERROR - Failed to import: /opt/airflow/dags/dag_with_postgres_operator.py
Traceback (most recent call last):
  File "/home/airflow/.local/lib/python3.8/site-packages/airflow/models/dagbag.py", line 344, in parse
    loader.exec_module(new_module)
  File "<frozen importlib._bootstrap_external>", line 843, in exec_module
  File "<frozen importlib._bootstrap>", line 219, in _call_with_frames_removed
  File "/opt/airflow/dags/dag_with_postgres_operator.py", line 20, in <module>
    task1 = BashOperator(
NameError: name 'BashOperator' is not defined
[2023-12-21T17:57:06.000+0000] {processor.py:842} WARNING - No viable dags retrieved from /opt/airflow/dags/dag_with_postgres_operator.py
[2023-12-21T17:57:06.744+0000] {processor.py:183} INFO - Processing /opt/airflow/dags/dag_with_postgres_operator.py took 1.531 seconds
[2023-12-21T17:57:37.298+0000] {processor.py:161} INFO - Started process (PID=3133) to work on /opt/airflow/dags/dag_with_postgres_operator.py
[2023-12-21T17:57:37.304+0000] {processor.py:830} INFO - Processing file /opt/airflow/dags/dag_with_postgres_operator.py for tasks to queue
[2023-12-21T17:57:37.312+0000] {logging_mixin.py:188} INFO - [2023-12-21T17:57:37.311+0000] {dagbag.py:538} INFO - Filling up the DagBag from /opt/airflow/dags/dag_with_postgres_operator.py
[2023-12-21T17:57:37.374+0000] {logging_mixin.py:188} INFO - [2023-12-21T17:57:37.359+0000] {dagbag.py:348} ERROR - Failed to import: /opt/airflow/dags/dag_with_postgres_operator.py
Traceback (most recent call last):
  File "/home/airflow/.local/lib/python3.8/site-packages/airflow/models/dagbag.py", line 344, in parse
    loader.exec_module(new_module)
  File "<frozen importlib._bootstrap_external>", line 843, in exec_module
  File "<frozen importlib._bootstrap>", line 219, in _call_with_frames_removed
  File "/opt/airflow/dags/dag_with_postgres_operator.py", line 20, in <module>
    task1 = BashOperator(
NameError: name 'BashOperator' is not defined
[2023-12-21T17:57:37.378+0000] {processor.py:842} WARNING - No viable dags retrieved from /opt/airflow/dags/dag_with_postgres_operator.py
[2023-12-21T17:57:37.429+0000] {processor.py:183} INFO - Processing /opt/airflow/dags/dag_with_postgres_operator.py took 0.143 seconds
[2023-12-21T17:57:46.831+0000] {processor.py:161} INFO - Started process (PID=3143) to work on /opt/airflow/dags/dag_with_postgres_operator.py
[2023-12-21T17:57:46.836+0000] {processor.py:830} INFO - Processing file /opt/airflow/dags/dag_with_postgres_operator.py for tasks to queue
[2023-12-21T17:57:46.840+0000] {logging_mixin.py:188} INFO - [2023-12-21T17:57:46.839+0000] {dagbag.py:538} INFO - Filling up the DagBag from /opt/airflow/dags/dag_with_postgres_operator.py
[2023-12-21T17:57:46.894+0000] {logging_mixin.py:188} INFO - [2023-12-21T17:57:46.883+0000] {dagbag.py:348} ERROR - Failed to import: /opt/airflow/dags/dag_with_postgres_operator.py
Traceback (most recent call last):
  File "/home/airflow/.local/lib/python3.8/site-packages/airflow/models/dagbag.py", line 344, in parse
    loader.exec_module(new_module)
  File "<frozen importlib._bootstrap_external>", line 843, in exec_module
  File "<frozen importlib._bootstrap>", line 219, in _call_with_frames_removed
  File "/opt/airflow/dags/dag_with_postgres_operator.py", line 20, in <module>
    task1 = PostgresOperator(
  File "/home/airflow/.local/lib/python3.8/site-packages/airflow/models/baseoperator.py", line 437, in apply_defaults
    result = func(self, **kwargs, default_args=default_args)
  File "/home/airflow/.local/lib/python3.8/site-packages/airflow/providers/postgres/operators/postgres.py", line 75, in __init__
    super().__init__(conn_id=postgres_conn_id, **kwargs)
  File "/home/airflow/.local/lib/python3.8/site-packages/airflow/models/baseoperator.py", line 420, in apply_defaults
    raise AirflowException(f"missing keyword argument {missing_args.pop()!r}")
airflow.exceptions.AirflowException: missing keyword argument 'sql'
[2023-12-21T17:57:46.898+0000] {processor.py:842} WARNING - No viable dags retrieved from /opt/airflow/dags/dag_with_postgres_operator.py
[2023-12-21T17:57:46.944+0000] {processor.py:183} INFO - Processing /opt/airflow/dags/dag_with_postgres_operator.py took 0.122 seconds
[2023-12-21T17:57:57.185+0000] {processor.py:161} INFO - Started process (PID=3148) to work on /opt/airflow/dags/dag_with_postgres_operator.py
[2023-12-21T17:57:57.188+0000] {processor.py:830} INFO - Processing file /opt/airflow/dags/dag_with_postgres_operator.py for tasks to queue
[2023-12-21T17:57:57.192+0000] {logging_mixin.py:188} INFO - [2023-12-21T17:57:57.192+0000] {dagbag.py:538} INFO - Filling up the DagBag from /opt/airflow/dags/dag_with_postgres_operator.py
[2023-12-21T17:57:57.238+0000] {logging_mixin.py:188} INFO - [2023-12-21T17:57:57.229+0000] {dagbag.py:348} ERROR - Failed to import: /opt/airflow/dags/dag_with_postgres_operator.py
Traceback (most recent call last):
  File "/home/airflow/.local/lib/python3.8/site-packages/airflow/models/dagbag.py", line 344, in parse
    loader.exec_module(new_module)
  File "<frozen importlib._bootstrap_external>", line 843, in exec_module
  File "<frozen importlib._bootstrap>", line 219, in _call_with_frames_removed
  File "/opt/airflow/dags/dag_with_postgres_operator.py", line 20, in <module>
    task1 = PostgresOperator(
  File "/home/airflow/.local/lib/python3.8/site-packages/airflow/models/baseoperator.py", line 437, in apply_defaults
    result = func(self, **kwargs, default_args=default_args)
  File "/home/airflow/.local/lib/python3.8/site-packages/airflow/providers/postgres/operators/postgres.py", line 75, in __init__
    super().__init__(conn_id=postgres_conn_id, **kwargs)
  File "/home/airflow/.local/lib/python3.8/site-packages/airflow/models/baseoperator.py", line 420, in apply_defaults
    raise AirflowException(f"missing keyword argument {missing_args.pop()!r}")
airflow.exceptions.AirflowException: missing keyword argument 'sql'
[2023-12-21T17:57:57.242+0000] {processor.py:842} WARNING - No viable dags retrieved from /opt/airflow/dags/dag_with_postgres_operator.py
[2023-12-21T17:57:57.286+0000] {processor.py:183} INFO - Processing /opt/airflow/dags/dag_with_postgres_operator.py took 0.111 seconds
[2023-12-21T17:58:15.589+0000] {processor.py:161} INFO - Started process (PID=3184) to work on /opt/airflow/dags/dag_with_postgres_operator.py
[2023-12-21T17:58:15.595+0000] {processor.py:830} INFO - Processing file /opt/airflow/dags/dag_with_postgres_operator.py for tasks to queue
[2023-12-21T17:58:15.600+0000] {logging_mixin.py:188} INFO - [2023-12-21T17:58:15.600+0000] {dagbag.py:538} INFO - Filling up the DagBag from /opt/airflow/dags/dag_with_postgres_operator.py
[2023-12-21T17:58:15.679+0000] {logging_mixin.py:188} INFO - [2023-12-21T17:58:15.671+0000] {dagbag.py:348} ERROR - Failed to import: /opt/airflow/dags/dag_with_postgres_operator.py
Traceback (most recent call last):
  File "/home/airflow/.local/lib/python3.8/site-packages/airflow/models/dagbag.py", line 344, in parse
    loader.exec_module(new_module)
  File "<frozen importlib._bootstrap_external>", line 843, in exec_module
  File "<frozen importlib._bootstrap>", line 219, in _call_with_frames_removed
  File "/opt/airflow/dags/dag_with_postgres_operator.py", line 20, in <module>
    task1 = PostgresOperator(
  File "/home/airflow/.local/lib/python3.8/site-packages/airflow/models/baseoperator.py", line 437, in apply_defaults
    result = func(self, **kwargs, default_args=default_args)
  File "/home/airflow/.local/lib/python3.8/site-packages/airflow/providers/postgres/operators/postgres.py", line 75, in __init__
    super().__init__(conn_id=postgres_conn_id, **kwargs)
  File "/home/airflow/.local/lib/python3.8/site-packages/airflow/models/baseoperator.py", line 420, in apply_defaults
    raise AirflowException(f"missing keyword argument {missing_args.pop()!r}")
airflow.exceptions.AirflowException: missing keyword argument 'sql'
[2023-12-21T17:58:15.684+0000] {processor.py:842} WARNING - No viable dags retrieved from /opt/airflow/dags/dag_with_postgres_operator.py
[2023-12-21T17:58:15.732+0000] {processor.py:183} INFO - Processing /opt/airflow/dags/dag_with_postgres_operator.py took 0.157 seconds
[2023-12-21T17:58:46.097+0000] {processor.py:161} INFO - Started process (PID=3224) to work on /opt/airflow/dags/dag_with_postgres_operator.py
[2023-12-21T17:58:46.102+0000] {processor.py:830} INFO - Processing file /opt/airflow/dags/dag_with_postgres_operator.py for tasks to queue
[2023-12-21T17:58:46.105+0000] {logging_mixin.py:188} INFO - [2023-12-21T17:58:46.104+0000] {dagbag.py:538} INFO - Filling up the DagBag from /opt/airflow/dags/dag_with_postgres_operator.py
[2023-12-21T17:58:46.136+0000] {logging_mixin.py:188} INFO - [2023-12-21T17:58:46.130+0000] {dagbag.py:348} ERROR - Failed to import: /opt/airflow/dags/dag_with_postgres_operator.py
Traceback (most recent call last):
  File "/home/airflow/.local/lib/python3.8/site-packages/airflow/models/dagbag.py", line 344, in parse
    loader.exec_module(new_module)
  File "<frozen importlib._bootstrap_external>", line 843, in exec_module
  File "<frozen importlib._bootstrap>", line 219, in _call_with_frames_removed
  File "/opt/airflow/dags/dag_with_postgres_operator.py", line 20, in <module>
    task1 = PostgresOperator(
  File "/home/airflow/.local/lib/python3.8/site-packages/airflow/models/baseoperator.py", line 437, in apply_defaults
    result = func(self, **kwargs, default_args=default_args)
  File "/home/airflow/.local/lib/python3.8/site-packages/airflow/providers/postgres/operators/postgres.py", line 75, in __init__
    super().__init__(conn_id=postgres_conn_id, **kwargs)
  File "/home/airflow/.local/lib/python3.8/site-packages/airflow/models/baseoperator.py", line 420, in apply_defaults
    raise AirflowException(f"missing keyword argument {missing_args.pop()!r}")
airflow.exceptions.AirflowException: missing keyword argument 'sql'
[2023-12-21T17:58:46.138+0000] {processor.py:842} WARNING - No viable dags retrieved from /opt/airflow/dags/dag_with_postgres_operator.py
[2023-12-21T17:58:46.176+0000] {processor.py:183} INFO - Processing /opt/airflow/dags/dag_with_postgres_operator.py took 0.085 seconds
[2023-12-21T17:59:16.262+0000] {processor.py:161} INFO - Started process (PID=3261) to work on /opt/airflow/dags/dag_with_postgres_operator.py
[2023-12-21T17:59:16.267+0000] {processor.py:830} INFO - Processing file /opt/airflow/dags/dag_with_postgres_operator.py for tasks to queue
[2023-12-21T17:59:16.277+0000] {logging_mixin.py:188} INFO - [2023-12-21T17:59:16.275+0000] {dagbag.py:538} INFO - Filling up the DagBag from /opt/airflow/dags/dag_with_postgres_operator.py
[2023-12-21T17:59:16.318+0000] {logging_mixin.py:188} INFO - [2023-12-21T17:59:16.313+0000] {dagbag.py:348} ERROR - Failed to import: /opt/airflow/dags/dag_with_postgres_operator.py
Traceback (most recent call last):
  File "/home/airflow/.local/lib/python3.8/site-packages/airflow/models/dagbag.py", line 344, in parse
    loader.exec_module(new_module)
  File "<frozen importlib._bootstrap_external>", line 843, in exec_module
  File "<frozen importlib._bootstrap>", line 219, in _call_with_frames_removed
  File "/opt/airflow/dags/dag_with_postgres_operator.py", line 20, in <module>
    task1 = PostgresOperator(
  File "/home/airflow/.local/lib/python3.8/site-packages/airflow/models/baseoperator.py", line 437, in apply_defaults
    result = func(self, **kwargs, default_args=default_args)
  File "/home/airflow/.local/lib/python3.8/site-packages/airflow/providers/postgres/operators/postgres.py", line 75, in __init__
    super().__init__(conn_id=postgres_conn_id, **kwargs)
  File "/home/airflow/.local/lib/python3.8/site-packages/airflow/models/baseoperator.py", line 420, in apply_defaults
    raise AirflowException(f"missing keyword argument {missing_args.pop()!r}")
airflow.exceptions.AirflowException: missing keyword argument 'sql'
[2023-12-21T17:59:16.323+0000] {processor.py:842} WARNING - No viable dags retrieved from /opt/airflow/dags/dag_with_postgres_operator.py
[2023-12-21T17:59:16.377+0000] {processor.py:183} INFO - Processing /opt/airflow/dags/dag_with_postgres_operator.py took 0.122 seconds
[2023-12-21T17:59:46.611+0000] {processor.py:161} INFO - Started process (PID=3299) to work on /opt/airflow/dags/dag_with_postgres_operator.py
[2023-12-21T17:59:46.614+0000] {processor.py:830} INFO - Processing file /opt/airflow/dags/dag_with_postgres_operator.py for tasks to queue
[2023-12-21T17:59:46.617+0000] {logging_mixin.py:188} INFO - [2023-12-21T17:59:46.617+0000] {dagbag.py:538} INFO - Filling up the DagBag from /opt/airflow/dags/dag_with_postgres_operator.py
[2023-12-21T17:59:46.642+0000] {logging_mixin.py:188} INFO - [2023-12-21T17:59:46.637+0000] {dagbag.py:348} ERROR - Failed to import: /opt/airflow/dags/dag_with_postgres_operator.py
Traceback (most recent call last):
  File "/home/airflow/.local/lib/python3.8/site-packages/airflow/models/dagbag.py", line 344, in parse
    loader.exec_module(new_module)
  File "<frozen importlib._bootstrap_external>", line 843, in exec_module
  File "<frozen importlib._bootstrap>", line 219, in _call_with_frames_removed
  File "/opt/airflow/dags/dag_with_postgres_operator.py", line 20, in <module>
    task1 = PostgresOperator(
  File "/home/airflow/.local/lib/python3.8/site-packages/airflow/models/baseoperator.py", line 437, in apply_defaults
    result = func(self, **kwargs, default_args=default_args)
  File "/home/airflow/.local/lib/python3.8/site-packages/airflow/providers/postgres/operators/postgres.py", line 75, in __init__
    super().__init__(conn_id=postgres_conn_id, **kwargs)
  File "/home/airflow/.local/lib/python3.8/site-packages/airflow/models/baseoperator.py", line 420, in apply_defaults
    raise AirflowException(f"missing keyword argument {missing_args.pop()!r}")
airflow.exceptions.AirflowException: missing keyword argument 'sql'
[2023-12-21T17:59:46.644+0000] {processor.py:842} WARNING - No viable dags retrieved from /opt/airflow/dags/dag_with_postgres_operator.py
[2023-12-21T17:59:46.686+0000] {processor.py:183} INFO - Processing /opt/airflow/dags/dag_with_postgres_operator.py took 0.087 seconds
[2023-12-21T18:00:17.001+0000] {processor.py:161} INFO - Started process (PID=3336) to work on /opt/airflow/dags/dag_with_postgres_operator.py
[2023-12-21T18:00:17.005+0000] {processor.py:830} INFO - Processing file /opt/airflow/dags/dag_with_postgres_operator.py for tasks to queue
[2023-12-21T18:00:17.010+0000] {logging_mixin.py:188} INFO - [2023-12-21T18:00:17.010+0000] {dagbag.py:538} INFO - Filling up the DagBag from /opt/airflow/dags/dag_with_postgres_operator.py
[2023-12-21T18:00:17.048+0000] {logging_mixin.py:188} INFO - [2023-12-21T18:00:17.037+0000] {dagbag.py:348} ERROR - Failed to import: /opt/airflow/dags/dag_with_postgres_operator.py
Traceback (most recent call last):
  File "/home/airflow/.local/lib/python3.8/site-packages/airflow/models/dagbag.py", line 344, in parse
    loader.exec_module(new_module)
  File "<frozen importlib._bootstrap_external>", line 843, in exec_module
  File "<frozen importlib._bootstrap>", line 219, in _call_with_frames_removed
  File "/opt/airflow/dags/dag_with_postgres_operator.py", line 20, in <module>
    task1 = PostgresOperator(
  File "/home/airflow/.local/lib/python3.8/site-packages/airflow/models/baseoperator.py", line 437, in apply_defaults
    result = func(self, **kwargs, default_args=default_args)
  File "/home/airflow/.local/lib/python3.8/site-packages/airflow/providers/postgres/operators/postgres.py", line 75, in __init__
    super().__init__(conn_id=postgres_conn_id, **kwargs)
  File "/home/airflow/.local/lib/python3.8/site-packages/airflow/models/baseoperator.py", line 420, in apply_defaults
    raise AirflowException(f"missing keyword argument {missing_args.pop()!r}")
airflow.exceptions.AirflowException: missing keyword argument 'sql'
[2023-12-21T18:00:17.051+0000] {processor.py:842} WARNING - No viable dags retrieved from /opt/airflow/dags/dag_with_postgres_operator.py
[2023-12-21T18:00:17.120+0000] {processor.py:183} INFO - Processing /opt/airflow/dags/dag_with_postgres_operator.py took 0.130 seconds
[2023-12-21T18:00:47.881+0000] {processor.py:161} INFO - Started process (PID=3372) to work on /opt/airflow/dags/dag_with_postgres_operator.py
[2023-12-21T18:00:47.887+0000] {processor.py:830} INFO - Processing file /opt/airflow/dags/dag_with_postgres_operator.py for tasks to queue
[2023-12-21T18:00:47.890+0000] {logging_mixin.py:188} INFO - [2023-12-21T18:00:47.889+0000] {dagbag.py:538} INFO - Filling up the DagBag from /opt/airflow/dags/dag_with_postgres_operator.py
[2023-12-21T18:00:47.931+0000] {logging_mixin.py:188} INFO - [2023-12-21T18:00:47.920+0000] {dagbag.py:348} ERROR - Failed to import: /opt/airflow/dags/dag_with_postgres_operator.py
Traceback (most recent call last):
  File "/home/airflow/.local/lib/python3.8/site-packages/airflow/models/dagbag.py", line 344, in parse
    loader.exec_module(new_module)
  File "<frozen importlib._bootstrap_external>", line 843, in exec_module
  File "<frozen importlib._bootstrap>", line 219, in _call_with_frames_removed
  File "/opt/airflow/dags/dag_with_postgres_operator.py", line 20, in <module>
    task1 = PostgresOperator(
  File "/home/airflow/.local/lib/python3.8/site-packages/airflow/models/baseoperator.py", line 437, in apply_defaults
    result = func(self, **kwargs, default_args=default_args)
  File "/home/airflow/.local/lib/python3.8/site-packages/airflow/providers/postgres/operators/postgres.py", line 75, in __init__
    super().__init__(conn_id=postgres_conn_id, **kwargs)
  File "/home/airflow/.local/lib/python3.8/site-packages/airflow/models/baseoperator.py", line 420, in apply_defaults
    raise AirflowException(f"missing keyword argument {missing_args.pop()!r}")
airflow.exceptions.AirflowException: missing keyword argument 'sql'
[2023-12-21T18:00:47.934+0000] {processor.py:842} WARNING - No viable dags retrieved from /opt/airflow/dags/dag_with_postgres_operator.py
[2023-12-21T18:00:48.077+0000] {processor.py:183} INFO - Processing /opt/airflow/dags/dag_with_postgres_operator.py took 0.203 seconds
[2023-12-21T18:01:16.356+0000] {processor.py:161} INFO - Started process (PID=3407) to work on /opt/airflow/dags/dag_with_postgres_operator.py
[2023-12-21T18:01:16.361+0000] {processor.py:830} INFO - Processing file /opt/airflow/dags/dag_with_postgres_operator.py for tasks to queue
[2023-12-21T18:01:16.374+0000] {logging_mixin.py:188} INFO - [2023-12-21T18:01:16.373+0000] {dagbag.py:538} INFO - Filling up the DagBag from /opt/airflow/dags/dag_with_postgres_operator.py
[2023-12-21T18:01:16.591+0000] {logging_mixin.py:188} INFO - [2023-12-21T18:01:16.583+0000] {dagbag.py:348} ERROR - Failed to import: /opt/airflow/dags/dag_with_postgres_operator.py
Traceback (most recent call last):
  File "/home/airflow/.local/lib/python3.8/site-packages/airflow/models/dagbag.py", line 344, in parse
    loader.exec_module(new_module)
  File "<frozen importlib._bootstrap_external>", line 843, in exec_module
  File "<frozen importlib._bootstrap>", line 219, in _call_with_frames_removed
  File "/opt/airflow/dags/dag_with_postgres_operator.py", line 20, in <module>
    task1 = PostgresOperator(
  File "/home/airflow/.local/lib/python3.8/site-packages/airflow/models/baseoperator.py", line 437, in apply_defaults
    result = func(self, **kwargs, default_args=default_args)
  File "/home/airflow/.local/lib/python3.8/site-packages/airflow/providers/postgres/operators/postgres.py", line 75, in __init__
    super().__init__(conn_id=postgres_conn_id, **kwargs)
  File "/home/airflow/.local/lib/python3.8/site-packages/airflow/models/baseoperator.py", line 420, in apply_defaults
    raise AirflowException(f"missing keyword argument {missing_args.pop()!r}")
airflow.exceptions.AirflowException: missing keyword argument 'sql'
[2023-12-21T18:01:16.593+0000] {processor.py:842} WARNING - No viable dags retrieved from /opt/airflow/dags/dag_with_postgres_operator.py
[2023-12-21T18:01:16.655+0000] {processor.py:183} INFO - Processing /opt/airflow/dags/dag_with_postgres_operator.py took 0.313 seconds
[2023-12-21T18:01:18.810+0000] {processor.py:161} INFO - Started process (PID=3412) to work on /opt/airflow/dags/dag_with_postgres_operator.py
[2023-12-21T18:01:18.833+0000] {processor.py:830} INFO - Processing file /opt/airflow/dags/dag_with_postgres_operator.py for tasks to queue
[2023-12-21T18:01:18.846+0000] {logging_mixin.py:188} INFO - [2023-12-21T18:01:18.845+0000] {dagbag.py:538} INFO - Filling up the DagBag from /opt/airflow/dags/dag_with_postgres_operator.py
[2023-12-21T18:01:18.968+0000] {logging_mixin.py:188} INFO - [2023-12-21T18:01:18.941+0000] {dagbag.py:348} ERROR - Failed to import: /opt/airflow/dags/dag_with_postgres_operator.py
Traceback (most recent call last):
  File "/home/airflow/.local/lib/python3.8/site-packages/airflow/models/dagbag.py", line 344, in parse
    loader.exec_module(new_module)
  File "<frozen importlib._bootstrap_external>", line 843, in exec_module
  File "<frozen importlib._bootstrap>", line 219, in _call_with_frames_removed
  File "/opt/airflow/dags/dag_with_postgres_operator.py", line 20, in <module>
    task1 = PostgresOperator(
  File "/home/airflow/.local/lib/python3.8/site-packages/airflow/models/baseoperator.py", line 437, in apply_defaults
    result = func(self, **kwargs, default_args=default_args)
  File "/home/airflow/.local/lib/python3.8/site-packages/airflow/providers/postgres/operators/postgres.py", line 75, in __init__
    super().__init__(conn_id=postgres_conn_id, **kwargs)
  File "/home/airflow/.local/lib/python3.8/site-packages/airflow/models/baseoperator.py", line 420, in apply_defaults
    raise AirflowException(f"missing keyword argument {missing_args.pop()!r}")
airflow.exceptions.AirflowException: missing keyword argument 'sql'
[2023-12-21T18:01:18.971+0000] {processor.py:842} WARNING - No viable dags retrieved from /opt/airflow/dags/dag_with_postgres_operator.py
[2023-12-21T18:01:19.026+0000] {processor.py:183} INFO - Processing /opt/airflow/dags/dag_with_postgres_operator.py took 0.224 seconds
[2023-12-21T18:01:49.190+0000] {processor.py:161} INFO - Started process (PID=3449) to work on /opt/airflow/dags/dag_with_postgres_operator.py
[2023-12-21T18:01:49.194+0000] {processor.py:830} INFO - Processing file /opt/airflow/dags/dag_with_postgres_operator.py for tasks to queue
[2023-12-21T18:01:49.202+0000] {logging_mixin.py:188} INFO - [2023-12-21T18:01:49.201+0000] {dagbag.py:538} INFO - Filling up the DagBag from /opt/airflow/dags/dag_with_postgres_operator.py
[2023-12-21T18:01:49.247+0000] {logging_mixin.py:188} INFO - [2023-12-21T18:01:49.241+0000] {dagbag.py:348} ERROR - Failed to import: /opt/airflow/dags/dag_with_postgres_operator.py
Traceback (most recent call last):
  File "/home/airflow/.local/lib/python3.8/site-packages/airflow/models/dagbag.py", line 344, in parse
    loader.exec_module(new_module)
  File "<frozen importlib._bootstrap_external>", line 843, in exec_module
  File "<frozen importlib._bootstrap>", line 219, in _call_with_frames_removed
  File "/opt/airflow/dags/dag_with_postgres_operator.py", line 20, in <module>
    task1 = PostgresOperator(
  File "/home/airflow/.local/lib/python3.8/site-packages/airflow/models/baseoperator.py", line 437, in apply_defaults
    result = func(self, **kwargs, default_args=default_args)
  File "/home/airflow/.local/lib/python3.8/site-packages/airflow/providers/postgres/operators/postgres.py", line 75, in __init__
    super().__init__(conn_id=postgres_conn_id, **kwargs)
  File "/home/airflow/.local/lib/python3.8/site-packages/airflow/models/baseoperator.py", line 420, in apply_defaults
    raise AirflowException(f"missing keyword argument {missing_args.pop()!r}")
airflow.exceptions.AirflowException: missing keyword argument 'sql'
[2023-12-21T18:01:49.250+0000] {processor.py:842} WARNING - No viable dags retrieved from /opt/airflow/dags/dag_with_postgres_operator.py
[2023-12-21T18:01:49.289+0000] {processor.py:183} INFO - Processing /opt/airflow/dags/dag_with_postgres_operator.py took 0.119 seconds
[2023-12-21T18:02:01.290+0000] {processor.py:161} INFO - Started process (PID=3454) to work on /opt/airflow/dags/dag_with_postgres_operator.py
[2023-12-21T18:02:01.293+0000] {processor.py:830} INFO - Processing file /opt/airflow/dags/dag_with_postgres_operator.py for tasks to queue
[2023-12-21T18:02:01.302+0000] {logging_mixin.py:188} INFO - [2023-12-21T18:02:01.298+0000] {dagbag.py:538} INFO - Filling up the DagBag from /opt/airflow/dags/dag_with_postgres_operator.py
[2023-12-21T18:02:01.427+0000] {logging_mixin.py:188} INFO - [2023-12-21T18:02:01.392+0000] {dagbag.py:348} ERROR - Failed to import: /opt/airflow/dags/dag_with_postgres_operator.py
Traceback (most recent call last):
  File "/home/airflow/.local/lib/python3.8/site-packages/airflow/models/dagbag.py", line 344, in parse
    loader.exec_module(new_module)
  File "<frozen importlib._bootstrap_external>", line 843, in exec_module
  File "<frozen importlib._bootstrap>", line 219, in _call_with_frames_removed
  File "/opt/airflow/dags/dag_with_postgres_operator.py", line 20, in <module>
    task1 = PostgresOperator(
  File "/home/airflow/.local/lib/python3.8/site-packages/airflow/models/baseoperator.py", line 437, in apply_defaults
    result = func(self, **kwargs, default_args=default_args)
  File "/home/airflow/.local/lib/python3.8/site-packages/airflow/providers/postgres/operators/postgres.py", line 75, in __init__
    super().__init__(conn_id=postgres_conn_id, **kwargs)
  File "/home/airflow/.local/lib/python3.8/site-packages/airflow/models/baseoperator.py", line 437, in apply_defaults
    result = func(self, **kwargs, default_args=default_args)
  File "/home/airflow/.local/lib/python3.8/site-packages/airflow/providers/common/sql/operators/sql.py", line 242, in __init__
    super().__init__(conn_id=conn_id, database=database, **kwargs)
  File "/home/airflow/.local/lib/python3.8/site-packages/airflow/models/baseoperator.py", line 437, in apply_defaults
    result = func(self, **kwargs, default_args=default_args)
  File "/home/airflow/.local/lib/python3.8/site-packages/airflow/providers/common/sql/operators/sql.py", line 139, in __init__
    super().__init__(**kwargs)
  File "/home/airflow/.local/lib/python3.8/site-packages/airflow/models/baseoperator.py", line 437, in apply_defaults
    result = func(self, **kwargs, default_args=default_args)
  File "/home/airflow/.local/lib/python3.8/site-packages/airflow/models/baseoperator.py", line 798, in __init__
    raise AirflowException(
airflow.exceptions.AirflowException: Invalid arguments were passed to PostgresOperator (task_id: create_postgres_table). Invalid arguments were:
**kwargs: {'postgres_connn_id': 'postgres_localhost'}
[2023-12-21T18:02:01.430+0000] {processor.py:842} WARNING - No viable dags retrieved from /opt/airflow/dags/dag_with_postgres_operator.py
[2023-12-21T18:02:01.521+0000] {processor.py:183} INFO - Processing /opt/airflow/dags/dag_with_postgres_operator.py took 0.241 seconds
[2023-12-21T18:02:12.429+0000] {processor.py:161} INFO - Started process (PID=3485) to work on /opt/airflow/dags/dag_with_postgres_operator.py
[2023-12-21T18:02:12.433+0000] {processor.py:830} INFO - Processing file /opt/airflow/dags/dag_with_postgres_operator.py for tasks to queue
[2023-12-21T18:02:12.436+0000] {logging_mixin.py:188} INFO - [2023-12-21T18:02:12.435+0000] {dagbag.py:538} INFO - Filling up the DagBag from /opt/airflow/dags/dag_with_postgres_operator.py
[2023-12-21T18:02:12.513+0000] {logging_mixin.py:188} INFO - [2023-12-21T18:02:12.481+0000] {dagbag.py:348} ERROR - Failed to import: /opt/airflow/dags/dag_with_postgres_operator.py
Traceback (most recent call last):
  File "/home/airflow/.local/lib/python3.8/site-packages/airflow/models/dagbag.py", line 344, in parse
    loader.exec_module(new_module)
  File "<frozen importlib._bootstrap_external>", line 843, in exec_module
  File "<frozen importlib._bootstrap>", line 219, in _call_with_frames_removed
  File "/opt/airflow/dags/dag_with_postgres_operator.py", line 20, in <module>
    task1 = PostgresOperator(
  File "/home/airflow/.local/lib/python3.8/site-packages/airflow/models/baseoperator.py", line 437, in apply_defaults
    result = func(self, **kwargs, default_args=default_args)
  File "/home/airflow/.local/lib/python3.8/site-packages/airflow/providers/postgres/operators/postgres.py", line 75, in __init__
    super().__init__(conn_id=postgres_conn_id, **kwargs)
  File "/home/airflow/.local/lib/python3.8/site-packages/airflow/models/baseoperator.py", line 437, in apply_defaults
    result = func(self, **kwargs, default_args=default_args)
  File "/home/airflow/.local/lib/python3.8/site-packages/airflow/providers/common/sql/operators/sql.py", line 242, in __init__
    super().__init__(conn_id=conn_id, database=database, **kwargs)
  File "/home/airflow/.local/lib/python3.8/site-packages/airflow/models/baseoperator.py", line 437, in apply_defaults
    result = func(self, **kwargs, default_args=default_args)
  File "/home/airflow/.local/lib/python3.8/site-packages/airflow/providers/common/sql/operators/sql.py", line 139, in __init__
    super().__init__(**kwargs)
  File "/home/airflow/.local/lib/python3.8/site-packages/airflow/models/baseoperator.py", line 437, in apply_defaults
    result = func(self, **kwargs, default_args=default_args)
  File "/home/airflow/.local/lib/python3.8/site-packages/airflow/models/baseoperator.py", line 798, in __init__
    raise AirflowException(
airflow.exceptions.AirflowException: Invalid arguments were passed to PostgresOperator (task_id: create_postgres_table). Invalid arguments were:
**kwargs: {'postgres_connn_id': 'postgres_localhost'}
[2023-12-21T18:02:12.522+0000] {processor.py:842} WARNING - No viable dags retrieved from /opt/airflow/dags/dag_with_postgres_operator.py
[2023-12-21T18:02:12.588+0000] {processor.py:183} INFO - Processing /opt/airflow/dags/dag_with_postgres_operator.py took 0.166 seconds
[2023-12-21T18:02:36.972+0000] {processor.py:161} INFO - Started process (PID=3495) to work on /opt/airflow/dags/dag_with_postgres_operator.py
[2023-12-21T18:02:36.980+0000] {processor.py:830} INFO - Processing file /opt/airflow/dags/dag_with_postgres_operator.py for tasks to queue
[2023-12-21T18:02:36.991+0000] {logging_mixin.py:188} INFO - [2023-12-21T18:02:36.988+0000] {dagbag.py:538} INFO - Filling up the DagBag from /opt/airflow/dags/dag_with_postgres_operator.py
[2023-12-21T18:02:37.097+0000] {logging_mixin.py:188} INFO - [2023-12-21T18:02:37.080+0000] {dagbag.py:348} ERROR - Failed to import: /opt/airflow/dags/dag_with_postgres_operator.py
Traceback (most recent call last):
  File "/home/airflow/.local/lib/python3.8/site-packages/airflow/models/dagbag.py", line 344, in parse
    loader.exec_module(new_module)
  File "<frozen importlib._bootstrap_external>", line 843, in exec_module
  File "<frozen importlib._bootstrap>", line 219, in _call_with_frames_removed
  File "/opt/airflow/dags/dag_with_postgres_operator.py", line 20, in <module>
    task1 = PostgresOperator(
  File "/home/airflow/.local/lib/python3.8/site-packages/airflow/models/baseoperator.py", line 437, in apply_defaults
    result = func(self, **kwargs, default_args=default_args)
  File "/home/airflow/.local/lib/python3.8/site-packages/airflow/providers/postgres/operators/postgres.py", line 75, in __init__
    super().__init__(conn_id=postgres_conn_id, **kwargs)
  File "/home/airflow/.local/lib/python3.8/site-packages/airflow/models/baseoperator.py", line 437, in apply_defaults
    result = func(self, **kwargs, default_args=default_args)
  File "/home/airflow/.local/lib/python3.8/site-packages/airflow/providers/common/sql/operators/sql.py", line 242, in __init__
    super().__init__(conn_id=conn_id, database=database, **kwargs)
  File "/home/airflow/.local/lib/python3.8/site-packages/airflow/models/baseoperator.py", line 437, in apply_defaults
    result = func(self, **kwargs, default_args=default_args)
  File "/home/airflow/.local/lib/python3.8/site-packages/airflow/providers/common/sql/operators/sql.py", line 139, in __init__
    super().__init__(**kwargs)
  File "/home/airflow/.local/lib/python3.8/site-packages/airflow/models/baseoperator.py", line 437, in apply_defaults
    result = func(self, **kwargs, default_args=default_args)
  File "/home/airflow/.local/lib/python3.8/site-packages/airflow/models/baseoperator.py", line 798, in __init__
    raise AirflowException(
airflow.exceptions.AirflowException: Invalid arguments were passed to PostgresOperator (task_id: create_postgres_table). Invalid arguments were:
**kwargs: {'postgres_connn_id': 'postgres_localhost'}
[2023-12-21T18:02:37.101+0000] {processor.py:842} WARNING - No viable dags retrieved from /opt/airflow/dags/dag_with_postgres_operator.py
[2023-12-21T18:02:37.166+0000] {processor.py:183} INFO - Processing /opt/airflow/dags/dag_with_postgres_operator.py took 0.209 seconds
[2023-12-21T18:02:44.651+0000] {processor.py:161} INFO - Started process (PID=3525) to work on /opt/airflow/dags/dag_with_postgres_operator.py
[2023-12-21T18:02:44.657+0000] {processor.py:830} INFO - Processing file /opt/airflow/dags/dag_with_postgres_operator.py for tasks to queue
[2023-12-21T18:02:44.662+0000] {logging_mixin.py:188} INFO - [2023-12-21T18:02:44.662+0000] {dagbag.py:538} INFO - Filling up the DagBag from /opt/airflow/dags/dag_with_postgres_operator.py
[2023-12-21T18:02:45.460+0000] {logging_mixin.py:188} INFO - [2023-12-21T18:02:45.299+0000] {dagbag.py:348} ERROR - Failed to import: /opt/airflow/dags/dag_with_postgres_operator.py
Traceback (most recent call last):
  File "/home/airflow/.local/lib/python3.8/site-packages/airflow/models/dagbag.py", line 344, in parse
    loader.exec_module(new_module)
  File "<frozen importlib._bootstrap_external>", line 843, in exec_module
  File "<frozen importlib._bootstrap>", line 219, in _call_with_frames_removed
  File "/opt/airflow/dags/dag_with_postgres_operator.py", line 20, in <module>
    task1 = PostgresOperator(
  File "/home/airflow/.local/lib/python3.8/site-packages/airflow/models/baseoperator.py", line 437, in apply_defaults
    result = func(self, **kwargs, default_args=default_args)
  File "/home/airflow/.local/lib/python3.8/site-packages/airflow/providers/postgres/operators/postgres.py", line 75, in __init__
    super().__init__(conn_id=postgres_conn_id, **kwargs)
  File "/home/airflow/.local/lib/python3.8/site-packages/airflow/models/baseoperator.py", line 437, in apply_defaults
    result = func(self, **kwargs, default_args=default_args)
  File "/home/airflow/.local/lib/python3.8/site-packages/airflow/providers/common/sql/operators/sql.py", line 242, in __init__
    super().__init__(conn_id=conn_id, database=database, **kwargs)
  File "/home/airflow/.local/lib/python3.8/site-packages/airflow/models/baseoperator.py", line 437, in apply_defaults
    result = func(self, **kwargs, default_args=default_args)
  File "/home/airflow/.local/lib/python3.8/site-packages/airflow/providers/common/sql/operators/sql.py", line 139, in __init__
    super().__init__(**kwargs)
  File "/home/airflow/.local/lib/python3.8/site-packages/airflow/models/baseoperator.py", line 437, in apply_defaults
    result = func(self, **kwargs, default_args=default_args)
  File "/home/airflow/.local/lib/python3.8/site-packages/airflow/models/baseoperator.py", line 798, in __init__
    raise AirflowException(
airflow.exceptions.AirflowException: Invalid arguments were passed to PostgresOperator (task_id: create_postgres_table). Invalid arguments were:
**kwargs: {'postgres_connn_id': 'postgres_localhost'}
[2023-12-21T18:02:45.498+0000] {processor.py:842} WARNING - No viable dags retrieved from /opt/airflow/dags/dag_with_postgres_operator.py
[2023-12-21T18:02:46.081+0000] {processor.py:183} INFO - Processing /opt/airflow/dags/dag_with_postgres_operator.py took 1.445 seconds
[2023-12-21T18:03:00.479+0000] {processor.py:161} INFO - Started process (PID=3535) to work on /opt/airflow/dags/dag_with_postgres_operator.py
[2023-12-21T18:03:00.485+0000] {processor.py:830} INFO - Processing file /opt/airflow/dags/dag_with_postgres_operator.py for tasks to queue
[2023-12-21T18:03:00.491+0000] {logging_mixin.py:188} INFO - [2023-12-21T18:03:00.490+0000] {dagbag.py:538} INFO - Filling up the DagBag from /opt/airflow/dags/dag_with_postgres_operator.py
[2023-12-21T18:03:00.546+0000] {logging_mixin.py:188} INFO - [2023-12-21T18:03:00.538+0000] {dagbag.py:348} ERROR - Failed to import: /opt/airflow/dags/dag_with_postgres_operator.py
Traceback (most recent call last):
  File "/home/airflow/.local/lib/python3.8/site-packages/airflow/models/dagbag.py", line 344, in parse
    loader.exec_module(new_module)
  File "<frozen importlib._bootstrap_external>", line 843, in exec_module
  File "<frozen importlib._bootstrap>", line 219, in _call_with_frames_removed
  File "/opt/airflow/dags/dag_with_postgres_operator.py", line 20, in <module>
    task1 = PostgresOperator(
  File "/home/airflow/.local/lib/python3.8/site-packages/airflow/models/baseoperator.py", line 437, in apply_defaults
    result = func(self, **kwargs, default_args=default_args)
  File "/home/airflow/.local/lib/python3.8/site-packages/airflow/providers/postgres/operators/postgres.py", line 75, in __init__
    super().__init__(conn_id=postgres_conn_id, **kwargs)
  File "/home/airflow/.local/lib/python3.8/site-packages/airflow/models/baseoperator.py", line 437, in apply_defaults
    result = func(self, **kwargs, default_args=default_args)
  File "/home/airflow/.local/lib/python3.8/site-packages/airflow/providers/common/sql/operators/sql.py", line 242, in __init__
    super().__init__(conn_id=conn_id, database=database, **kwargs)
  File "/home/airflow/.local/lib/python3.8/site-packages/airflow/models/baseoperator.py", line 437, in apply_defaults
    result = func(self, **kwargs, default_args=default_args)
  File "/home/airflow/.local/lib/python3.8/site-packages/airflow/providers/common/sql/operators/sql.py", line 139, in __init__
    super().__init__(**kwargs)
  File "/home/airflow/.local/lib/python3.8/site-packages/airflow/models/baseoperator.py", line 437, in apply_defaults
    result = func(self, **kwargs, default_args=default_args)
  File "/home/airflow/.local/lib/python3.8/site-packages/airflow/models/baseoperator.py", line 798, in __init__
    raise AirflowException(
airflow.exceptions.AirflowException: Invalid arguments were passed to PostgresOperator (task_id: create_postgres_table). Invalid arguments were:
**kwargs: {'postgres_connn_id': 'postgres_localhost'}
[2023-12-21T18:03:00.550+0000] {processor.py:842} WARNING - No viable dags retrieved from /opt/airflow/dags/dag_with_postgres_operator.py
[2023-12-21T18:03:00.606+0000] {processor.py:183} INFO - Processing /opt/airflow/dags/dag_with_postgres_operator.py took 0.139 seconds
[2023-12-21T18:03:06.602+0000] {processor.py:161} INFO - Started process (PID=3540) to work on /opt/airflow/dags/dag_with_postgres_operator.py
[2023-12-21T18:03:06.609+0000] {processor.py:830} INFO - Processing file /opt/airflow/dags/dag_with_postgres_operator.py for tasks to queue
[2023-12-21T18:03:06.613+0000] {logging_mixin.py:188} INFO - [2023-12-21T18:03:06.612+0000] {dagbag.py:538} INFO - Filling up the DagBag from /opt/airflow/dags/dag_with_postgres_operator.py
[2023-12-21T18:03:06.673+0000] {logging_mixin.py:188} INFO - [2023-12-21T18:03:06.663+0000] {dagbag.py:348} ERROR - Failed to import: /opt/airflow/dags/dag_with_postgres_operator.py
Traceback (most recent call last):
  File "/home/airflow/.local/lib/python3.8/site-packages/airflow/models/dagbag.py", line 344, in parse
    loader.exec_module(new_module)
  File "<frozen importlib._bootstrap_external>", line 843, in exec_module
  File "<frozen importlib._bootstrap>", line 219, in _call_with_frames_removed
  File "/opt/airflow/dags/dag_with_postgres_operator.py", line 20, in <module>
    task1 = PostgresOperator(
  File "/home/airflow/.local/lib/python3.8/site-packages/airflow/models/baseoperator.py", line 437, in apply_defaults
    result = func(self, **kwargs, default_args=default_args)
  File "/home/airflow/.local/lib/python3.8/site-packages/airflow/providers/postgres/operators/postgres.py", line 75, in __init__
    super().__init__(conn_id=postgres_conn_id, **kwargs)
  File "/home/airflow/.local/lib/python3.8/site-packages/airflow/models/baseoperator.py", line 437, in apply_defaults
    result = func(self, **kwargs, default_args=default_args)
  File "/home/airflow/.local/lib/python3.8/site-packages/airflow/providers/common/sql/operators/sql.py", line 242, in __init__
    super().__init__(conn_id=conn_id, database=database, **kwargs)
  File "/home/airflow/.local/lib/python3.8/site-packages/airflow/models/baseoperator.py", line 437, in apply_defaults
    result = func(self, **kwargs, default_args=default_args)
  File "/home/airflow/.local/lib/python3.8/site-packages/airflow/providers/common/sql/operators/sql.py", line 139, in __init__
    super().__init__(**kwargs)
  File "/home/airflow/.local/lib/python3.8/site-packages/airflow/models/baseoperator.py", line 437, in apply_defaults
    result = func(self, **kwargs, default_args=default_args)
  File "/home/airflow/.local/lib/python3.8/site-packages/airflow/models/baseoperator.py", line 798, in __init__
    raise AirflowException(
airflow.exceptions.AirflowException: Invalid arguments were passed to PostgresOperator (task_id: create_postgres_table). Invalid arguments were:
**kwargs: {'postgres_connn_id': 'postgres_localhost'}
[2023-12-21T18:03:06.676+0000] {processor.py:842} WARNING - No viable dags retrieved from /opt/airflow/dags/dag_with_postgres_operator.py
[2023-12-21T18:03:06.725+0000] {processor.py:183} INFO - Processing /opt/airflow/dags/dag_with_postgres_operator.py took 0.131 seconds
[2023-12-21T18:03:13.604+0000] {processor.py:161} INFO - Started process (PID=3570) to work on /opt/airflow/dags/dag_with_postgres_operator.py
[2023-12-21T18:03:13.614+0000] {processor.py:830} INFO - Processing file /opt/airflow/dags/dag_with_postgres_operator.py for tasks to queue
[2023-12-21T18:03:13.624+0000] {logging_mixin.py:188} INFO - [2023-12-21T18:03:13.622+0000] {dagbag.py:538} INFO - Filling up the DagBag from /opt/airflow/dags/dag_with_postgres_operator.py
[2023-12-21T18:03:13.687+0000] {logging_mixin.py:188} INFO - [2023-12-21T18:03:13.682+0000] {dagbag.py:348} ERROR - Failed to import: /opt/airflow/dags/dag_with_postgres_operator.py
Traceback (most recent call last):
  File "/home/airflow/.local/lib/python3.8/site-packages/airflow/models/dagbag.py", line 344, in parse
    loader.exec_module(new_module)
  File "<frozen importlib._bootstrap_external>", line 843, in exec_module
  File "<frozen importlib._bootstrap>", line 219, in _call_with_frames_removed
  File "/opt/airflow/dags/dag_with_postgres_operator.py", line 20, in <module>
    task1 = PostgresOperator(
  File "/home/airflow/.local/lib/python3.8/site-packages/airflow/models/baseoperator.py", line 437, in apply_defaults
    result = func(self, **kwargs, default_args=default_args)
  File "/home/airflow/.local/lib/python3.8/site-packages/airflow/providers/postgres/operators/postgres.py", line 75, in __init__
    super().__init__(conn_id=postgres_conn_id, **kwargs)
  File "/home/airflow/.local/lib/python3.8/site-packages/airflow/models/baseoperator.py", line 437, in apply_defaults
    result = func(self, **kwargs, default_args=default_args)
  File "/home/airflow/.local/lib/python3.8/site-packages/airflow/providers/common/sql/operators/sql.py", line 242, in __init__
    super().__init__(conn_id=conn_id, database=database, **kwargs)
  File "/home/airflow/.local/lib/python3.8/site-packages/airflow/models/baseoperator.py", line 437, in apply_defaults
    result = func(self, **kwargs, default_args=default_args)
  File "/home/airflow/.local/lib/python3.8/site-packages/airflow/providers/common/sql/operators/sql.py", line 139, in __init__
    super().__init__(**kwargs)
  File "/home/airflow/.local/lib/python3.8/site-packages/airflow/models/baseoperator.py", line 437, in apply_defaults
    result = func(self, **kwargs, default_args=default_args)
  File "/home/airflow/.local/lib/python3.8/site-packages/airflow/models/baseoperator.py", line 798, in __init__
    raise AirflowException(
airflow.exceptions.AirflowException: Invalid arguments were passed to PostgresOperator (task_id: create_postgres_table). Invalid arguments were:
**kwargs: {'postgres_connn_id': 'postgres_localhost'}
[2023-12-21T18:03:13.691+0000] {processor.py:842} WARNING - No viable dags retrieved from /opt/airflow/dags/dag_with_postgres_operator.py
[2023-12-21T18:03:13.810+0000] {processor.py:183} INFO - Processing /opt/airflow/dags/dag_with_postgres_operator.py took 0.232 seconds
[2023-12-21T18:03:29.104+0000] {processor.py:161} INFO - Started process (PID=3582) to work on /opt/airflow/dags/dag_with_postgres_operator.py
[2023-12-21T18:03:29.108+0000] {processor.py:830} INFO - Processing file /opt/airflow/dags/dag_with_postgres_operator.py for tasks to queue
[2023-12-21T18:03:29.117+0000] {logging_mixin.py:188} INFO - [2023-12-21T18:03:29.114+0000] {dagbag.py:538} INFO - Filling up the DagBag from /opt/airflow/dags/dag_with_postgres_operator.py
[2023-12-21T18:03:29.184+0000] {logging_mixin.py:188} INFO - [2023-12-21T18:03:29.173+0000] {dagbag.py:348} ERROR - Failed to import: /opt/airflow/dags/dag_with_postgres_operator.py
Traceback (most recent call last):
  File "/home/airflow/.local/lib/python3.8/site-packages/airflow/models/dagbag.py", line 344, in parse
    loader.exec_module(new_module)
  File "<frozen importlib._bootstrap_external>", line 843, in exec_module
  File "<frozen importlib._bootstrap>", line 219, in _call_with_frames_removed
  File "/opt/airflow/dags/dag_with_postgres_operator.py", line 20, in <module>
    task1 = PostgresOperator(
  File "/home/airflow/.local/lib/python3.8/site-packages/airflow/models/baseoperator.py", line 437, in apply_defaults
    result = func(self, **kwargs, default_args=default_args)
  File "/home/airflow/.local/lib/python3.8/site-packages/airflow/providers/postgres/operators/postgres.py", line 75, in __init__
    super().__init__(conn_id=postgres_conn_id, **kwargs)
  File "/home/airflow/.local/lib/python3.8/site-packages/airflow/models/baseoperator.py", line 437, in apply_defaults
    result = func(self, **kwargs, default_args=default_args)
  File "/home/airflow/.local/lib/python3.8/site-packages/airflow/providers/common/sql/operators/sql.py", line 242, in __init__
    super().__init__(conn_id=conn_id, database=database, **kwargs)
  File "/home/airflow/.local/lib/python3.8/site-packages/airflow/models/baseoperator.py", line 437, in apply_defaults
    result = func(self, **kwargs, default_args=default_args)
  File "/home/airflow/.local/lib/python3.8/site-packages/airflow/providers/common/sql/operators/sql.py", line 139, in __init__
    super().__init__(**kwargs)
  File "/home/airflow/.local/lib/python3.8/site-packages/airflow/models/baseoperator.py", line 437, in apply_defaults
    result = func(self, **kwargs, default_args=default_args)
  File "/home/airflow/.local/lib/python3.8/site-packages/airflow/models/baseoperator.py", line 798, in __init__
    raise AirflowException(
airflow.exceptions.AirflowException: Invalid arguments were passed to PostgresOperator (task_id: create_postgres_table). Invalid arguments were:
**kwargs: {'postgres_connn_id': 'postgres_localhost'}
[2023-12-21T18:03:29.190+0000] {processor.py:842} WARNING - No viable dags retrieved from /opt/airflow/dags/dag_with_postgres_operator.py
[2023-12-21T18:03:29.237+0000] {processor.py:183} INFO - Processing /opt/airflow/dags/dag_with_postgres_operator.py took 0.145 seconds
[2023-12-21T18:03:47.395+0000] {processor.py:161} INFO - Started process (PID=3613) to work on /opt/airflow/dags/dag_with_postgres_operator.py
[2023-12-21T18:03:47.399+0000] {processor.py:830} INFO - Processing file /opt/airflow/dags/dag_with_postgres_operator.py for tasks to queue
[2023-12-21T18:03:47.403+0000] {logging_mixin.py:188} INFO - [2023-12-21T18:03:47.403+0000] {dagbag.py:538} INFO - Filling up the DagBag from /opt/airflow/dags/dag_with_postgres_operator.py
[2023-12-21T18:03:47.480+0000] {logging_mixin.py:188} INFO - [2023-12-21T18:03:47.461+0000] {dagbag.py:348} ERROR - Failed to import: /opt/airflow/dags/dag_with_postgres_operator.py
Traceback (most recent call last):
  File "/home/airflow/.local/lib/python3.8/site-packages/airflow/models/dagbag.py", line 344, in parse
    loader.exec_module(new_module)
  File "<frozen importlib._bootstrap_external>", line 843, in exec_module
  File "<frozen importlib._bootstrap>", line 219, in _call_with_frames_removed
  File "/opt/airflow/dags/dag_with_postgres_operator.py", line 20, in <module>
    task1 = PostgresOperator(
  File "/home/airflow/.local/lib/python3.8/site-packages/airflow/models/baseoperator.py", line 437, in apply_defaults
    result = func(self, **kwargs, default_args=default_args)
  File "/home/airflow/.local/lib/python3.8/site-packages/airflow/providers/postgres/operators/postgres.py", line 75, in __init__
    super().__init__(conn_id=postgres_conn_id, **kwargs)
  File "/home/airflow/.local/lib/python3.8/site-packages/airflow/models/baseoperator.py", line 437, in apply_defaults
    result = func(self, **kwargs, default_args=default_args)
  File "/home/airflow/.local/lib/python3.8/site-packages/airflow/providers/common/sql/operators/sql.py", line 242, in __init__
    super().__init__(conn_id=conn_id, database=database, **kwargs)
  File "/home/airflow/.local/lib/python3.8/site-packages/airflow/models/baseoperator.py", line 437, in apply_defaults
    result = func(self, **kwargs, default_args=default_args)
  File "/home/airflow/.local/lib/python3.8/site-packages/airflow/providers/common/sql/operators/sql.py", line 139, in __init__
    super().__init__(**kwargs)
  File "/home/airflow/.local/lib/python3.8/site-packages/airflow/models/baseoperator.py", line 437, in apply_defaults
    result = func(self, **kwargs, default_args=default_args)
  File "/home/airflow/.local/lib/python3.8/site-packages/airflow/models/baseoperator.py", line 798, in __init__
    raise AirflowException(
airflow.exceptions.AirflowException: Invalid arguments were passed to PostgresOperator (task_id: create_postgres_table). Invalid arguments were:
**kwargs: {'postgres_connn_id': 'postgres_localhost'}
[2023-12-21T18:03:47.493+0000] {processor.py:842} WARNING - No viable dags retrieved from /opt/airflow/dags/dag_with_postgres_operator.py
[2023-12-21T18:03:47.618+0000] {processor.py:183} INFO - Processing /opt/airflow/dags/dag_with_postgres_operator.py took 0.236 seconds
[2023-12-21T18:03:58.906+0000] {processor.py:161} INFO - Started process (PID=3623) to work on /opt/airflow/dags/dag_with_postgres_operator.py
[2023-12-21T18:03:58.910+0000] {processor.py:830} INFO - Processing file /opt/airflow/dags/dag_with_postgres_operator.py for tasks to queue
[2023-12-21T18:03:58.913+0000] {logging_mixin.py:188} INFO - [2023-12-21T18:03:58.913+0000] {dagbag.py:538} INFO - Filling up the DagBag from /opt/airflow/dags/dag_with_postgres_operator.py
[2023-12-21T18:03:58.972+0000] {logging_mixin.py:188} INFO - [2023-12-21T18:03:58.965+0000] {dagbag.py:348} ERROR - Failed to import: /opt/airflow/dags/dag_with_postgres_operator.py
Traceback (most recent call last):
  File "/home/airflow/.local/lib/python3.8/site-packages/airflow/models/dagbag.py", line 344, in parse
    loader.exec_module(new_module)
  File "<frozen importlib._bootstrap_external>", line 843, in exec_module
  File "<frozen importlib._bootstrap>", line 219, in _call_with_frames_removed
  File "/opt/airflow/dags/dag_with_postgres_operator.py", line 20, in <module>
    task1 = PostgresOperator(
  File "/home/airflow/.local/lib/python3.8/site-packages/airflow/models/baseoperator.py", line 437, in apply_defaults
    result = func(self, **kwargs, default_args=default_args)
  File "/home/airflow/.local/lib/python3.8/site-packages/airflow/providers/postgres/operators/postgres.py", line 75, in __init__
    super().__init__(conn_id=postgres_conn_id, **kwargs)
  File "/home/airflow/.local/lib/python3.8/site-packages/airflow/models/baseoperator.py", line 437, in apply_defaults
    result = func(self, **kwargs, default_args=default_args)
  File "/home/airflow/.local/lib/python3.8/site-packages/airflow/providers/common/sql/operators/sql.py", line 242, in __init__
    super().__init__(conn_id=conn_id, database=database, **kwargs)
  File "/home/airflow/.local/lib/python3.8/site-packages/airflow/models/baseoperator.py", line 437, in apply_defaults
    result = func(self, **kwargs, default_args=default_args)
  File "/home/airflow/.local/lib/python3.8/site-packages/airflow/providers/common/sql/operators/sql.py", line 139, in __init__
    super().__init__(**kwargs)
  File "/home/airflow/.local/lib/python3.8/site-packages/airflow/models/baseoperator.py", line 437, in apply_defaults
    result = func(self, **kwargs, default_args=default_args)
  File "/home/airflow/.local/lib/python3.8/site-packages/airflow/models/baseoperator.py", line 798, in __init__
    raise AirflowException(
airflow.exceptions.AirflowException: Invalid arguments were passed to PostgresOperator (task_id: create_postgres_table). Invalid arguments were:
**kwargs: {'postgres_connn_id': 'postgres_localhost'}
[2023-12-21T18:03:58.975+0000] {processor.py:842} WARNING - No viable dags retrieved from /opt/airflow/dags/dag_with_postgres_operator.py
[2023-12-21T18:03:59.021+0000] {processor.py:183} INFO - Processing /opt/airflow/dags/dag_with_postgres_operator.py took 0.127 seconds
[2023-12-21T18:04:29.190+0000] {processor.py:161} INFO - Started process (PID=3659) to work on /opt/airflow/dags/dag_with_postgres_operator.py
[2023-12-21T18:04:29.195+0000] {processor.py:830} INFO - Processing file /opt/airflow/dags/dag_with_postgres_operator.py for tasks to queue
[2023-12-21T18:04:29.203+0000] {logging_mixin.py:188} INFO - [2023-12-21T18:04:29.201+0000] {dagbag.py:538} INFO - Filling up the DagBag from /opt/airflow/dags/dag_with_postgres_operator.py
[2023-12-21T18:04:29.258+0000] {logging_mixin.py:188} INFO - [2023-12-21T18:04:29.248+0000] {dagbag.py:348} ERROR - Failed to import: /opt/airflow/dags/dag_with_postgres_operator.py
Traceback (most recent call last):
  File "/home/airflow/.local/lib/python3.8/site-packages/airflow/models/dagbag.py", line 344, in parse
    loader.exec_module(new_module)
  File "<frozen importlib._bootstrap_external>", line 843, in exec_module
  File "<frozen importlib._bootstrap>", line 219, in _call_with_frames_removed
  File "/opt/airflow/dags/dag_with_postgres_operator.py", line 20, in <module>
    task1 = PostgresOperator(
  File "/home/airflow/.local/lib/python3.8/site-packages/airflow/models/baseoperator.py", line 437, in apply_defaults
    result = func(self, **kwargs, default_args=default_args)
  File "/home/airflow/.local/lib/python3.8/site-packages/airflow/providers/postgres/operators/postgres.py", line 75, in __init__
    super().__init__(conn_id=postgres_conn_id, **kwargs)
  File "/home/airflow/.local/lib/python3.8/site-packages/airflow/models/baseoperator.py", line 437, in apply_defaults
    result = func(self, **kwargs, default_args=default_args)
  File "/home/airflow/.local/lib/python3.8/site-packages/airflow/providers/common/sql/operators/sql.py", line 242, in __init__
    super().__init__(conn_id=conn_id, database=database, **kwargs)
  File "/home/airflow/.local/lib/python3.8/site-packages/airflow/models/baseoperator.py", line 437, in apply_defaults
    result = func(self, **kwargs, default_args=default_args)
  File "/home/airflow/.local/lib/python3.8/site-packages/airflow/providers/common/sql/operators/sql.py", line 139, in __init__
    super().__init__(**kwargs)
  File "/home/airflow/.local/lib/python3.8/site-packages/airflow/models/baseoperator.py", line 437, in apply_defaults
    result = func(self, **kwargs, default_args=default_args)
  File "/home/airflow/.local/lib/python3.8/site-packages/airflow/models/baseoperator.py", line 798, in __init__
    raise AirflowException(
airflow.exceptions.AirflowException: Invalid arguments were passed to PostgresOperator (task_id: create_postgres_table). Invalid arguments were:
**kwargs: {'postgres_connn_id': 'postgres_localhost'}
[2023-12-21T18:04:29.265+0000] {processor.py:842} WARNING - No viable dags retrieved from /opt/airflow/dags/dag_with_postgres_operator.py
[2023-12-21T18:04:29.315+0000] {processor.py:183} INFO - Processing /opt/airflow/dags/dag_with_postgres_operator.py took 0.137 seconds
[2023-12-21T18:04:37.332+0000] {processor.py:161} INFO - Started process (PID=3664) to work on /opt/airflow/dags/dag_with_postgres_operator.py
[2023-12-21T18:04:37.338+0000] {processor.py:830} INFO - Processing file /opt/airflow/dags/dag_with_postgres_operator.py for tasks to queue
[2023-12-21T18:04:37.347+0000] {logging_mixin.py:188} INFO - [2023-12-21T18:04:37.346+0000] {dagbag.py:538} INFO - Filling up the DagBag from /opt/airflow/dags/dag_with_postgres_operator.py
[2023-12-21T18:04:37.409+0000] {logging_mixin.py:188} INFO - [2023-12-21T18:04:37.401+0000] {dagbag.py:348} ERROR - Failed to import: /opt/airflow/dags/dag_with_postgres_operator.py
Traceback (most recent call last):
  File "/home/airflow/.local/lib/python3.8/site-packages/airflow/models/dagbag.py", line 344, in parse
    loader.exec_module(new_module)
  File "<frozen importlib._bootstrap_external>", line 843, in exec_module
  File "<frozen importlib._bootstrap>", line 219, in _call_with_frames_removed
  File "/opt/airflow/dags/dag_with_postgres_operator.py", line 20, in <module>
    task1 = PostgresOperator(
  File "/home/airflow/.local/lib/python3.8/site-packages/airflow/models/baseoperator.py", line 437, in apply_defaults
    result = func(self, **kwargs, default_args=default_args)
  File "/home/airflow/.local/lib/python3.8/site-packages/airflow/providers/postgres/operators/postgres.py", line 75, in __init__
    super().__init__(conn_id=postgres_conn_id, **kwargs)
  File "/home/airflow/.local/lib/python3.8/site-packages/airflow/models/baseoperator.py", line 437, in apply_defaults
    result = func(self, **kwargs, default_args=default_args)
  File "/home/airflow/.local/lib/python3.8/site-packages/airflow/providers/common/sql/operators/sql.py", line 242, in __init__
    super().__init__(conn_id=conn_id, database=database, **kwargs)
  File "/home/airflow/.local/lib/python3.8/site-packages/airflow/models/baseoperator.py", line 437, in apply_defaults
    result = func(self, **kwargs, default_args=default_args)
  File "/home/airflow/.local/lib/python3.8/site-packages/airflow/providers/common/sql/operators/sql.py", line 139, in __init__
    super().__init__(**kwargs)
  File "/home/airflow/.local/lib/python3.8/site-packages/airflow/models/baseoperator.py", line 437, in apply_defaults
    result = func(self, **kwargs, default_args=default_args)
  File "/home/airflow/.local/lib/python3.8/site-packages/airflow/models/baseoperator.py", line 798, in __init__
    raise AirflowException(
airflow.exceptions.AirflowException: Invalid arguments were passed to PostgresOperator (task_id: create_postgres_table). Invalid arguments were:
**kwargs: {'postgres_connn_id': 'postgres_localhost'}
[2023-12-21T18:04:37.414+0000] {processor.py:842} WARNING - No viable dags retrieved from /opt/airflow/dags/dag_with_postgres_operator.py
[2023-12-21T18:04:37.485+0000] {processor.py:183} INFO - Processing /opt/airflow/dags/dag_with_postgres_operator.py took 0.166 seconds
[2023-12-21T18:05:07.948+0000] {processor.py:161} INFO - Started process (PID=3702) to work on /opt/airflow/dags/dag_with_postgres_operator.py
[2023-12-21T18:05:07.951+0000] {processor.py:830} INFO - Processing file /opt/airflow/dags/dag_with_postgres_operator.py for tasks to queue
[2023-12-21T18:05:07.953+0000] {logging_mixin.py:188} INFO - [2023-12-21T18:05:07.953+0000] {dagbag.py:538} INFO - Filling up the DagBag from /opt/airflow/dags/dag_with_postgres_operator.py
[2023-12-21T18:05:07.985+0000] {logging_mixin.py:188} INFO - [2023-12-21T18:05:07.979+0000] {dagbag.py:348} ERROR - Failed to import: /opt/airflow/dags/dag_with_postgres_operator.py
Traceback (most recent call last):
  File "/home/airflow/.local/lib/python3.8/site-packages/airflow/models/dagbag.py", line 344, in parse
    loader.exec_module(new_module)
  File "<frozen importlib._bootstrap_external>", line 843, in exec_module
  File "<frozen importlib._bootstrap>", line 219, in _call_with_frames_removed
  File "/opt/airflow/dags/dag_with_postgres_operator.py", line 20, in <module>
    task1 = PostgresOperator(
  File "/home/airflow/.local/lib/python3.8/site-packages/airflow/models/baseoperator.py", line 437, in apply_defaults
    result = func(self, **kwargs, default_args=default_args)
  File "/home/airflow/.local/lib/python3.8/site-packages/airflow/providers/postgres/operators/postgres.py", line 75, in __init__
    super().__init__(conn_id=postgres_conn_id, **kwargs)
  File "/home/airflow/.local/lib/python3.8/site-packages/airflow/models/baseoperator.py", line 437, in apply_defaults
    result = func(self, **kwargs, default_args=default_args)
  File "/home/airflow/.local/lib/python3.8/site-packages/airflow/providers/common/sql/operators/sql.py", line 242, in __init__
    super().__init__(conn_id=conn_id, database=database, **kwargs)
  File "/home/airflow/.local/lib/python3.8/site-packages/airflow/models/baseoperator.py", line 437, in apply_defaults
    result = func(self, **kwargs, default_args=default_args)
  File "/home/airflow/.local/lib/python3.8/site-packages/airflow/providers/common/sql/operators/sql.py", line 139, in __init__
    super().__init__(**kwargs)
  File "/home/airflow/.local/lib/python3.8/site-packages/airflow/models/baseoperator.py", line 437, in apply_defaults
    result = func(self, **kwargs, default_args=default_args)
  File "/home/airflow/.local/lib/python3.8/site-packages/airflow/models/baseoperator.py", line 798, in __init__
    raise AirflowException(
airflow.exceptions.AirflowException: Invalid arguments were passed to PostgresOperator (task_id: create_postgres_table). Invalid arguments were:
**kwargs: {'postgres_connn_id': 'postgres_localhost'}
[2023-12-21T18:05:07.987+0000] {processor.py:842} WARNING - No viable dags retrieved from /opt/airflow/dags/dag_with_postgres_operator.py
[2023-12-21T18:05:08.041+0000] {processor.py:183} INFO - Processing /opt/airflow/dags/dag_with_postgres_operator.py took 0.104 seconds
[2023-12-21T18:05:38.458+0000] {processor.py:161} INFO - Started process (PID=3740) to work on /opt/airflow/dags/dag_with_postgres_operator.py
[2023-12-21T18:05:38.461+0000] {processor.py:830} INFO - Processing file /opt/airflow/dags/dag_with_postgres_operator.py for tasks to queue
[2023-12-21T18:05:38.465+0000] {logging_mixin.py:188} INFO - [2023-12-21T18:05:38.464+0000] {dagbag.py:538} INFO - Filling up the DagBag from /opt/airflow/dags/dag_with_postgres_operator.py
[2023-12-21T18:05:38.498+0000] {logging_mixin.py:188} INFO - [2023-12-21T18:05:38.491+0000] {dagbag.py:348} ERROR - Failed to import: /opt/airflow/dags/dag_with_postgres_operator.py
Traceback (most recent call last):
  File "/home/airflow/.local/lib/python3.8/site-packages/airflow/models/dagbag.py", line 344, in parse
    loader.exec_module(new_module)
  File "<frozen importlib._bootstrap_external>", line 843, in exec_module
  File "<frozen importlib._bootstrap>", line 219, in _call_with_frames_removed
  File "/opt/airflow/dags/dag_with_postgres_operator.py", line 20, in <module>
    task1 = PostgresOperator(
  File "/home/airflow/.local/lib/python3.8/site-packages/airflow/models/baseoperator.py", line 437, in apply_defaults
    result = func(self, **kwargs, default_args=default_args)
  File "/home/airflow/.local/lib/python3.8/site-packages/airflow/providers/postgres/operators/postgres.py", line 75, in __init__
    super().__init__(conn_id=postgres_conn_id, **kwargs)
  File "/home/airflow/.local/lib/python3.8/site-packages/airflow/models/baseoperator.py", line 437, in apply_defaults
    result = func(self, **kwargs, default_args=default_args)
  File "/home/airflow/.local/lib/python3.8/site-packages/airflow/providers/common/sql/operators/sql.py", line 242, in __init__
    super().__init__(conn_id=conn_id, database=database, **kwargs)
  File "/home/airflow/.local/lib/python3.8/site-packages/airflow/models/baseoperator.py", line 437, in apply_defaults
    result = func(self, **kwargs, default_args=default_args)
  File "/home/airflow/.local/lib/python3.8/site-packages/airflow/providers/common/sql/operators/sql.py", line 139, in __init__
    super().__init__(**kwargs)
  File "/home/airflow/.local/lib/python3.8/site-packages/airflow/models/baseoperator.py", line 437, in apply_defaults
    result = func(self, **kwargs, default_args=default_args)
  File "/home/airflow/.local/lib/python3.8/site-packages/airflow/models/baseoperator.py", line 798, in __init__
    raise AirflowException(
airflow.exceptions.AirflowException: Invalid arguments were passed to PostgresOperator (task_id: create_postgres_table). Invalid arguments were:
**kwargs: {'postgres_connn_id': 'postgres_localhost'}
[2023-12-21T18:05:38.501+0000] {processor.py:842} WARNING - No viable dags retrieved from /opt/airflow/dags/dag_with_postgres_operator.py
[2023-12-21T18:05:38.550+0000] {processor.py:183} INFO - Processing /opt/airflow/dags/dag_with_postgres_operator.py took 0.104 seconds
[2023-12-21T18:06:08.901+0000] {processor.py:161} INFO - Started process (PID=3777) to work on /opt/airflow/dags/dag_with_postgres_operator.py
[2023-12-21T18:06:08.909+0000] {processor.py:830} INFO - Processing file /opt/airflow/dags/dag_with_postgres_operator.py for tasks to queue
[2023-12-21T18:06:08.923+0000] {logging_mixin.py:188} INFO - [2023-12-21T18:06:08.918+0000] {dagbag.py:538} INFO - Filling up the DagBag from /opt/airflow/dags/dag_with_postgres_operator.py
[2023-12-21T18:06:08.971+0000] {logging_mixin.py:188} INFO - [2023-12-21T18:06:08.961+0000] {dagbag.py:348} ERROR - Failed to import: /opt/airflow/dags/dag_with_postgres_operator.py
Traceback (most recent call last):
  File "/home/airflow/.local/lib/python3.8/site-packages/airflow/models/dagbag.py", line 344, in parse
    loader.exec_module(new_module)
  File "<frozen importlib._bootstrap_external>", line 843, in exec_module
  File "<frozen importlib._bootstrap>", line 219, in _call_with_frames_removed
  File "/opt/airflow/dags/dag_with_postgres_operator.py", line 20, in <module>
    task1 = PostgresOperator(
  File "/home/airflow/.local/lib/python3.8/site-packages/airflow/models/baseoperator.py", line 437, in apply_defaults
    result = func(self, **kwargs, default_args=default_args)
  File "/home/airflow/.local/lib/python3.8/site-packages/airflow/providers/postgres/operators/postgres.py", line 75, in __init__
    super().__init__(conn_id=postgres_conn_id, **kwargs)
  File "/home/airflow/.local/lib/python3.8/site-packages/airflow/models/baseoperator.py", line 437, in apply_defaults
    result = func(self, **kwargs, default_args=default_args)
  File "/home/airflow/.local/lib/python3.8/site-packages/airflow/providers/common/sql/operators/sql.py", line 242, in __init__
    super().__init__(conn_id=conn_id, database=database, **kwargs)
  File "/home/airflow/.local/lib/python3.8/site-packages/airflow/models/baseoperator.py", line 437, in apply_defaults
    result = func(self, **kwargs, default_args=default_args)
  File "/home/airflow/.local/lib/python3.8/site-packages/airflow/providers/common/sql/operators/sql.py", line 139, in __init__
    super().__init__(**kwargs)
  File "/home/airflow/.local/lib/python3.8/site-packages/airflow/models/baseoperator.py", line 437, in apply_defaults
    result = func(self, **kwargs, default_args=default_args)
  File "/home/airflow/.local/lib/python3.8/site-packages/airflow/models/baseoperator.py", line 798, in __init__
    raise AirflowException(
airflow.exceptions.AirflowException: Invalid arguments were passed to PostgresOperator (task_id: create_postgres_table). Invalid arguments were:
**kwargs: {'postgres_connn_id': 'postgres_localhost'}
[2023-12-21T18:06:08.993+0000] {processor.py:842} WARNING - No viable dags retrieved from /opt/airflow/dags/dag_with_postgres_operator.py
[2023-12-21T18:06:09.133+0000] {processor.py:183} INFO - Processing /opt/airflow/dags/dag_with_postgres_operator.py took 0.254 seconds
[2023-12-21T18:06:39.814+0000] {processor.py:161} INFO - Started process (PID=3813) to work on /opt/airflow/dags/dag_with_postgres_operator.py
[2023-12-21T18:06:39.818+0000] {processor.py:830} INFO - Processing file /opt/airflow/dags/dag_with_postgres_operator.py for tasks to queue
[2023-12-21T18:06:39.820+0000] {logging_mixin.py:188} INFO - [2023-12-21T18:06:39.820+0000] {dagbag.py:538} INFO - Filling up the DagBag from /opt/airflow/dags/dag_with_postgres_operator.py
[2023-12-21T18:06:39.860+0000] {logging_mixin.py:188} INFO - [2023-12-21T18:06:39.850+0000] {dagbag.py:348} ERROR - Failed to import: /opt/airflow/dags/dag_with_postgres_operator.py
Traceback (most recent call last):
  File "/home/airflow/.local/lib/python3.8/site-packages/airflow/models/dagbag.py", line 344, in parse
    loader.exec_module(new_module)
  File "<frozen importlib._bootstrap_external>", line 843, in exec_module
  File "<frozen importlib._bootstrap>", line 219, in _call_with_frames_removed
  File "/opt/airflow/dags/dag_with_postgres_operator.py", line 20, in <module>
    task1 = PostgresOperator(
  File "/home/airflow/.local/lib/python3.8/site-packages/airflow/models/baseoperator.py", line 437, in apply_defaults
    result = func(self, **kwargs, default_args=default_args)
  File "/home/airflow/.local/lib/python3.8/site-packages/airflow/providers/postgres/operators/postgres.py", line 75, in __init__
    super().__init__(conn_id=postgres_conn_id, **kwargs)
  File "/home/airflow/.local/lib/python3.8/site-packages/airflow/models/baseoperator.py", line 437, in apply_defaults
    result = func(self, **kwargs, default_args=default_args)
  File "/home/airflow/.local/lib/python3.8/site-packages/airflow/providers/common/sql/operators/sql.py", line 242, in __init__
    super().__init__(conn_id=conn_id, database=database, **kwargs)
  File "/home/airflow/.local/lib/python3.8/site-packages/airflow/models/baseoperator.py", line 437, in apply_defaults
    result = func(self, **kwargs, default_args=default_args)
  File "/home/airflow/.local/lib/python3.8/site-packages/airflow/providers/common/sql/operators/sql.py", line 139, in __init__
    super().__init__(**kwargs)
  File "/home/airflow/.local/lib/python3.8/site-packages/airflow/models/baseoperator.py", line 437, in apply_defaults
    result = func(self, **kwargs, default_args=default_args)
  File "/home/airflow/.local/lib/python3.8/site-packages/airflow/models/baseoperator.py", line 798, in __init__
    raise AirflowException(
airflow.exceptions.AirflowException: Invalid arguments were passed to PostgresOperator (task_id: create_postgres_table). Invalid arguments were:
**kwargs: {'postgres_connn_id': 'postgres_localhost'}
[2023-12-21T18:06:39.862+0000] {processor.py:842} WARNING - No viable dags retrieved from /opt/airflow/dags/dag_with_postgres_operator.py
[2023-12-21T18:06:39.910+0000] {processor.py:183} INFO - Processing /opt/airflow/dags/dag_with_postgres_operator.py took 0.105 seconds
[2023-12-21T18:07:10.067+0000] {processor.py:161} INFO - Started process (PID=3851) to work on /opt/airflow/dags/dag_with_postgres_operator.py
[2023-12-21T18:07:10.070+0000] {processor.py:830} INFO - Processing file /opt/airflow/dags/dag_with_postgres_operator.py for tasks to queue
[2023-12-21T18:07:10.073+0000] {logging_mixin.py:188} INFO - [2023-12-21T18:07:10.072+0000] {dagbag.py:538} INFO - Filling up the DagBag from /opt/airflow/dags/dag_with_postgres_operator.py
[2023-12-21T18:07:10.101+0000] {logging_mixin.py:188} INFO - [2023-12-21T18:07:10.094+0000] {dagbag.py:348} ERROR - Failed to import: /opt/airflow/dags/dag_with_postgres_operator.py
Traceback (most recent call last):
  File "/home/airflow/.local/lib/python3.8/site-packages/airflow/models/dagbag.py", line 344, in parse
    loader.exec_module(new_module)
  File "<frozen importlib._bootstrap_external>", line 843, in exec_module
  File "<frozen importlib._bootstrap>", line 219, in _call_with_frames_removed
  File "/opt/airflow/dags/dag_with_postgres_operator.py", line 20, in <module>
    task1 = PostgresOperator(
  File "/home/airflow/.local/lib/python3.8/site-packages/airflow/models/baseoperator.py", line 437, in apply_defaults
    result = func(self, **kwargs, default_args=default_args)
  File "/home/airflow/.local/lib/python3.8/site-packages/airflow/providers/postgres/operators/postgres.py", line 75, in __init__
    super().__init__(conn_id=postgres_conn_id, **kwargs)
  File "/home/airflow/.local/lib/python3.8/site-packages/airflow/models/baseoperator.py", line 437, in apply_defaults
    result = func(self, **kwargs, default_args=default_args)
  File "/home/airflow/.local/lib/python3.8/site-packages/airflow/providers/common/sql/operators/sql.py", line 242, in __init__
    super().__init__(conn_id=conn_id, database=database, **kwargs)
  File "/home/airflow/.local/lib/python3.8/site-packages/airflow/models/baseoperator.py", line 437, in apply_defaults
    result = func(self, **kwargs, default_args=default_args)
  File "/home/airflow/.local/lib/python3.8/site-packages/airflow/providers/common/sql/operators/sql.py", line 139, in __init__
    super().__init__(**kwargs)
  File "/home/airflow/.local/lib/python3.8/site-packages/airflow/models/baseoperator.py", line 437, in apply_defaults
    result = func(self, **kwargs, default_args=default_args)
  File "/home/airflow/.local/lib/python3.8/site-packages/airflow/models/baseoperator.py", line 798, in __init__
    raise AirflowException(
airflow.exceptions.AirflowException: Invalid arguments were passed to PostgresOperator (task_id: create_postgres_table). Invalid arguments were:
**kwargs: {'postgres_connn_id': 'postgres_localhost'}
[2023-12-21T18:07:10.103+0000] {processor.py:842} WARNING - No viable dags retrieved from /opt/airflow/dags/dag_with_postgres_operator.py
[2023-12-21T18:07:10.141+0000] {processor.py:183} INFO - Processing /opt/airflow/dags/dag_with_postgres_operator.py took 0.081 seconds
[2023-12-21T18:07:40.554+0000] {processor.py:161} INFO - Started process (PID=3894) to work on /opt/airflow/dags/dag_with_postgres_operator.py
[2023-12-21T18:07:40.564+0000] {processor.py:830} INFO - Processing file /opt/airflow/dags/dag_with_postgres_operator.py for tasks to queue
[2023-12-21T18:07:40.576+0000] {logging_mixin.py:188} INFO - [2023-12-21T18:07:40.574+0000] {dagbag.py:538} INFO - Filling up the DagBag from /opt/airflow/dags/dag_with_postgres_operator.py
[2023-12-21T18:07:40.630+0000] {logging_mixin.py:188} INFO - [2023-12-21T18:07:40.622+0000] {dagbag.py:348} ERROR - Failed to import: /opt/airflow/dags/dag_with_postgres_operator.py
Traceback (most recent call last):
  File "/home/airflow/.local/lib/python3.8/site-packages/airflow/models/dagbag.py", line 344, in parse
    loader.exec_module(new_module)
  File "<frozen importlib._bootstrap_external>", line 843, in exec_module
  File "<frozen importlib._bootstrap>", line 219, in _call_with_frames_removed
  File "/opt/airflow/dags/dag_with_postgres_operator.py", line 20, in <module>
    task1 = PostgresOperator(
  File "/home/airflow/.local/lib/python3.8/site-packages/airflow/models/baseoperator.py", line 437, in apply_defaults
    result = func(self, **kwargs, default_args=default_args)
  File "/home/airflow/.local/lib/python3.8/site-packages/airflow/providers/postgres/operators/postgres.py", line 75, in __init__
    super().__init__(conn_id=postgres_conn_id, **kwargs)
  File "/home/airflow/.local/lib/python3.8/site-packages/airflow/models/baseoperator.py", line 437, in apply_defaults
    result = func(self, **kwargs, default_args=default_args)
  File "/home/airflow/.local/lib/python3.8/site-packages/airflow/providers/common/sql/operators/sql.py", line 242, in __init__
    super().__init__(conn_id=conn_id, database=database, **kwargs)
  File "/home/airflow/.local/lib/python3.8/site-packages/airflow/models/baseoperator.py", line 437, in apply_defaults
    result = func(self, **kwargs, default_args=default_args)
  File "/home/airflow/.local/lib/python3.8/site-packages/airflow/providers/common/sql/operators/sql.py", line 139, in __init__
    super().__init__(**kwargs)
  File "/home/airflow/.local/lib/python3.8/site-packages/airflow/models/baseoperator.py", line 437, in apply_defaults
    result = func(self, **kwargs, default_args=default_args)
  File "/home/airflow/.local/lib/python3.8/site-packages/airflow/models/baseoperator.py", line 798, in __init__
    raise AirflowException(
airflow.exceptions.AirflowException: Invalid arguments were passed to PostgresOperator (task_id: create_postgres_table). Invalid arguments were:
**kwargs: {'postgres_connn_id': 'postgres_localhost'}
[2023-12-21T18:07:40.635+0000] {processor.py:842} WARNING - No viable dags retrieved from /opt/airflow/dags/dag_with_postgres_operator.py
[2023-12-21T18:07:40.675+0000] {processor.py:183} INFO - Processing /opt/airflow/dags/dag_with_postgres_operator.py took 0.129 seconds
[2023-12-21T18:08:10.879+0000] {processor.py:161} INFO - Started process (PID=3930) to work on /opt/airflow/dags/dag_with_postgres_operator.py
[2023-12-21T18:08:10.883+0000] {processor.py:830} INFO - Processing file /opt/airflow/dags/dag_with_postgres_operator.py for tasks to queue
[2023-12-21T18:08:10.886+0000] {logging_mixin.py:188} INFO - [2023-12-21T18:08:10.885+0000] {dagbag.py:538} INFO - Filling up the DagBag from /opt/airflow/dags/dag_with_postgres_operator.py
[2023-12-21T18:08:10.952+0000] {logging_mixin.py:188} INFO - [2023-12-21T18:08:10.943+0000] {dagbag.py:348} ERROR - Failed to import: /opt/airflow/dags/dag_with_postgres_operator.py
Traceback (most recent call last):
  File "/home/airflow/.local/lib/python3.8/site-packages/airflow/models/dagbag.py", line 344, in parse
    loader.exec_module(new_module)
  File "<frozen importlib._bootstrap_external>", line 843, in exec_module
  File "<frozen importlib._bootstrap>", line 219, in _call_with_frames_removed
  File "/opt/airflow/dags/dag_with_postgres_operator.py", line 20, in <module>
    task1 = PostgresOperator(
  File "/home/airflow/.local/lib/python3.8/site-packages/airflow/models/baseoperator.py", line 437, in apply_defaults
    result = func(self, **kwargs, default_args=default_args)
  File "/home/airflow/.local/lib/python3.8/site-packages/airflow/providers/postgres/operators/postgres.py", line 75, in __init__
    super().__init__(conn_id=postgres_conn_id, **kwargs)
  File "/home/airflow/.local/lib/python3.8/site-packages/airflow/models/baseoperator.py", line 437, in apply_defaults
    result = func(self, **kwargs, default_args=default_args)
  File "/home/airflow/.local/lib/python3.8/site-packages/airflow/providers/common/sql/operators/sql.py", line 242, in __init__
    super().__init__(conn_id=conn_id, database=database, **kwargs)
  File "/home/airflow/.local/lib/python3.8/site-packages/airflow/models/baseoperator.py", line 437, in apply_defaults
    result = func(self, **kwargs, default_args=default_args)
  File "/home/airflow/.local/lib/python3.8/site-packages/airflow/providers/common/sql/operators/sql.py", line 139, in __init__
    super().__init__(**kwargs)
  File "/home/airflow/.local/lib/python3.8/site-packages/airflow/models/baseoperator.py", line 437, in apply_defaults
    result = func(self, **kwargs, default_args=default_args)
  File "/home/airflow/.local/lib/python3.8/site-packages/airflow/models/baseoperator.py", line 798, in __init__
    raise AirflowException(
airflow.exceptions.AirflowException: Invalid arguments were passed to PostgresOperator (task_id: create_postgres_table). Invalid arguments were:
**kwargs: {'postgres_connn_id': 'postgres_localhost'}
[2023-12-21T18:08:10.956+0000] {processor.py:842} WARNING - No viable dags retrieved from /opt/airflow/dags/dag_with_postgres_operator.py
[2023-12-21T18:08:11.008+0000] {processor.py:183} INFO - Processing /opt/airflow/dags/dag_with_postgres_operator.py took 0.147 seconds
[2023-12-21T18:08:41.171+0000] {processor.py:161} INFO - Started process (PID=3967) to work on /opt/airflow/dags/dag_with_postgres_operator.py
[2023-12-21T18:08:41.175+0000] {processor.py:830} INFO - Processing file /opt/airflow/dags/dag_with_postgres_operator.py for tasks to queue
[2023-12-21T18:08:41.178+0000] {logging_mixin.py:188} INFO - [2023-12-21T18:08:41.178+0000] {dagbag.py:538} INFO - Filling up the DagBag from /opt/airflow/dags/dag_with_postgres_operator.py
[2023-12-21T18:08:41.211+0000] {logging_mixin.py:188} INFO - [2023-12-21T18:08:41.202+0000] {dagbag.py:348} ERROR - Failed to import: /opt/airflow/dags/dag_with_postgres_operator.py
Traceback (most recent call last):
  File "/home/airflow/.local/lib/python3.8/site-packages/airflow/models/dagbag.py", line 344, in parse
    loader.exec_module(new_module)
  File "<frozen importlib._bootstrap_external>", line 843, in exec_module
  File "<frozen importlib._bootstrap>", line 219, in _call_with_frames_removed
  File "/opt/airflow/dags/dag_with_postgres_operator.py", line 20, in <module>
    task1 = PostgresOperator(
  File "/home/airflow/.local/lib/python3.8/site-packages/airflow/models/baseoperator.py", line 437, in apply_defaults
    result = func(self, **kwargs, default_args=default_args)
  File "/home/airflow/.local/lib/python3.8/site-packages/airflow/providers/postgres/operators/postgres.py", line 75, in __init__
    super().__init__(conn_id=postgres_conn_id, **kwargs)
  File "/home/airflow/.local/lib/python3.8/site-packages/airflow/models/baseoperator.py", line 437, in apply_defaults
    result = func(self, **kwargs, default_args=default_args)
  File "/home/airflow/.local/lib/python3.8/site-packages/airflow/providers/common/sql/operators/sql.py", line 242, in __init__
    super().__init__(conn_id=conn_id, database=database, **kwargs)
  File "/home/airflow/.local/lib/python3.8/site-packages/airflow/models/baseoperator.py", line 437, in apply_defaults
    result = func(self, **kwargs, default_args=default_args)
  File "/home/airflow/.local/lib/python3.8/site-packages/airflow/providers/common/sql/operators/sql.py", line 139, in __init__
    super().__init__(**kwargs)
  File "/home/airflow/.local/lib/python3.8/site-packages/airflow/models/baseoperator.py", line 437, in apply_defaults
    result = func(self, **kwargs, default_args=default_args)
  File "/home/airflow/.local/lib/python3.8/site-packages/airflow/models/baseoperator.py", line 798, in __init__
    raise AirflowException(
airflow.exceptions.AirflowException: Invalid arguments were passed to PostgresOperator (task_id: create_postgres_table). Invalid arguments were:
**kwargs: {'postgres_connn_id': 'postgres_localhost'}
[2023-12-21T18:08:41.213+0000] {processor.py:842} WARNING - No viable dags retrieved from /opt/airflow/dags/dag_with_postgres_operator.py
[2023-12-21T18:08:41.255+0000] {processor.py:183} INFO - Processing /opt/airflow/dags/dag_with_postgres_operator.py took 0.096 seconds
[2023-12-21T18:09:11.715+0000] {processor.py:161} INFO - Started process (PID=4004) to work on /opt/airflow/dags/dag_with_postgres_operator.py
[2023-12-21T18:09:11.719+0000] {processor.py:830} INFO - Processing file /opt/airflow/dags/dag_with_postgres_operator.py for tasks to queue
[2023-12-21T18:09:11.725+0000] {logging_mixin.py:188} INFO - [2023-12-21T18:09:11.723+0000] {dagbag.py:538} INFO - Filling up the DagBag from /opt/airflow/dags/dag_with_postgres_operator.py
[2023-12-21T18:09:11.779+0000] {logging_mixin.py:188} INFO - [2023-12-21T18:09:11.766+0000] {dagbag.py:348} ERROR - Failed to import: /opt/airflow/dags/dag_with_postgres_operator.py
Traceback (most recent call last):
  File "/home/airflow/.local/lib/python3.8/site-packages/airflow/models/dagbag.py", line 344, in parse
    loader.exec_module(new_module)
  File "<frozen importlib._bootstrap_external>", line 843, in exec_module
  File "<frozen importlib._bootstrap>", line 219, in _call_with_frames_removed
  File "/opt/airflow/dags/dag_with_postgres_operator.py", line 20, in <module>
    task1 = PostgresOperator(
  File "/home/airflow/.local/lib/python3.8/site-packages/airflow/models/baseoperator.py", line 437, in apply_defaults
    result = func(self, **kwargs, default_args=default_args)
  File "/home/airflow/.local/lib/python3.8/site-packages/airflow/providers/postgres/operators/postgres.py", line 75, in __init__
    super().__init__(conn_id=postgres_conn_id, **kwargs)
  File "/home/airflow/.local/lib/python3.8/site-packages/airflow/models/baseoperator.py", line 437, in apply_defaults
    result = func(self, **kwargs, default_args=default_args)
  File "/home/airflow/.local/lib/python3.8/site-packages/airflow/providers/common/sql/operators/sql.py", line 242, in __init__
    super().__init__(conn_id=conn_id, database=database, **kwargs)
  File "/home/airflow/.local/lib/python3.8/site-packages/airflow/models/baseoperator.py", line 437, in apply_defaults
    result = func(self, **kwargs, default_args=default_args)
  File "/home/airflow/.local/lib/python3.8/site-packages/airflow/providers/common/sql/operators/sql.py", line 139, in __init__
    super().__init__(**kwargs)
  File "/home/airflow/.local/lib/python3.8/site-packages/airflow/models/baseoperator.py", line 437, in apply_defaults
    result = func(self, **kwargs, default_args=default_args)
  File "/home/airflow/.local/lib/python3.8/site-packages/airflow/models/baseoperator.py", line 798, in __init__
    raise AirflowException(
airflow.exceptions.AirflowException: Invalid arguments were passed to PostgresOperator (task_id: create_postgres_table). Invalid arguments were:
**kwargs: {'postgres_connn_id': 'postgres_localhost'}
[2023-12-21T18:09:11.782+0000] {processor.py:842} WARNING - No viable dags retrieved from /opt/airflow/dags/dag_with_postgres_operator.py
[2023-12-21T18:09:11.844+0000] {processor.py:183} INFO - Processing /opt/airflow/dags/dag_with_postgres_operator.py took 0.135 seconds
[2023-12-21T18:09:41.966+0000] {processor.py:161} INFO - Started process (PID=4040) to work on /opt/airflow/dags/dag_with_postgres_operator.py
[2023-12-21T18:09:41.970+0000] {processor.py:830} INFO - Processing file /opt/airflow/dags/dag_with_postgres_operator.py for tasks to queue
[2023-12-21T18:09:41.973+0000] {logging_mixin.py:188} INFO - [2023-12-21T18:09:41.972+0000] {dagbag.py:538} INFO - Filling up the DagBag from /opt/airflow/dags/dag_with_postgres_operator.py
[2023-12-21T18:09:42.013+0000] {logging_mixin.py:188} INFO - [2023-12-21T18:09:42.007+0000] {dagbag.py:348} ERROR - Failed to import: /opt/airflow/dags/dag_with_postgres_operator.py
Traceback (most recent call last):
  File "/home/airflow/.local/lib/python3.8/site-packages/airflow/models/dagbag.py", line 344, in parse
    loader.exec_module(new_module)
  File "<frozen importlib._bootstrap_external>", line 843, in exec_module
  File "<frozen importlib._bootstrap>", line 219, in _call_with_frames_removed
  File "/opt/airflow/dags/dag_with_postgres_operator.py", line 20, in <module>
    task1 = PostgresOperator(
  File "/home/airflow/.local/lib/python3.8/site-packages/airflow/models/baseoperator.py", line 437, in apply_defaults
    result = func(self, **kwargs, default_args=default_args)
  File "/home/airflow/.local/lib/python3.8/site-packages/airflow/providers/postgres/operators/postgres.py", line 75, in __init__
    super().__init__(conn_id=postgres_conn_id, **kwargs)
  File "/home/airflow/.local/lib/python3.8/site-packages/airflow/models/baseoperator.py", line 437, in apply_defaults
    result = func(self, **kwargs, default_args=default_args)
  File "/home/airflow/.local/lib/python3.8/site-packages/airflow/providers/common/sql/operators/sql.py", line 242, in __init__
    super().__init__(conn_id=conn_id, database=database, **kwargs)
  File "/home/airflow/.local/lib/python3.8/site-packages/airflow/models/baseoperator.py", line 437, in apply_defaults
    result = func(self, **kwargs, default_args=default_args)
  File "/home/airflow/.local/lib/python3.8/site-packages/airflow/providers/common/sql/operators/sql.py", line 139, in __init__
    super().__init__(**kwargs)
  File "/home/airflow/.local/lib/python3.8/site-packages/airflow/models/baseoperator.py", line 437, in apply_defaults
    result = func(self, **kwargs, default_args=default_args)
  File "/home/airflow/.local/lib/python3.8/site-packages/airflow/models/baseoperator.py", line 798, in __init__
    raise AirflowException(
airflow.exceptions.AirflowException: Invalid arguments were passed to PostgresOperator (task_id: create_postgres_table). Invalid arguments were:
**kwargs: {'postgres_connn_id': 'postgres_localhost'}
[2023-12-21T18:09:42.016+0000] {processor.py:842} WARNING - No viable dags retrieved from /opt/airflow/dags/dag_with_postgres_operator.py
[2023-12-21T18:09:42.064+0000] {processor.py:183} INFO - Processing /opt/airflow/dags/dag_with_postgres_operator.py took 0.104 seconds
[2023-12-21T18:10:12.351+0000] {processor.py:161} INFO - Started process (PID=4077) to work on /opt/airflow/dags/dag_with_postgres_operator.py
[2023-12-21T18:10:12.354+0000] {processor.py:830} INFO - Processing file /opt/airflow/dags/dag_with_postgres_operator.py for tasks to queue
[2023-12-21T18:10:12.359+0000] {logging_mixin.py:188} INFO - [2023-12-21T18:10:12.358+0000] {dagbag.py:538} INFO - Filling up the DagBag from /opt/airflow/dags/dag_with_postgres_operator.py
[2023-12-21T18:10:12.399+0000] {logging_mixin.py:188} INFO - [2023-12-21T18:10:12.388+0000] {dagbag.py:348} ERROR - Failed to import: /opt/airflow/dags/dag_with_postgres_operator.py
Traceback (most recent call last):
  File "/home/airflow/.local/lib/python3.8/site-packages/airflow/models/dagbag.py", line 344, in parse
    loader.exec_module(new_module)
  File "<frozen importlib._bootstrap_external>", line 843, in exec_module
  File "<frozen importlib._bootstrap>", line 219, in _call_with_frames_removed
  File "/opt/airflow/dags/dag_with_postgres_operator.py", line 20, in <module>
    task1 = PostgresOperator(
  File "/home/airflow/.local/lib/python3.8/site-packages/airflow/models/baseoperator.py", line 437, in apply_defaults
    result = func(self, **kwargs, default_args=default_args)
  File "/home/airflow/.local/lib/python3.8/site-packages/airflow/providers/postgres/operators/postgres.py", line 75, in __init__
    super().__init__(conn_id=postgres_conn_id, **kwargs)
  File "/home/airflow/.local/lib/python3.8/site-packages/airflow/models/baseoperator.py", line 437, in apply_defaults
    result = func(self, **kwargs, default_args=default_args)
  File "/home/airflow/.local/lib/python3.8/site-packages/airflow/providers/common/sql/operators/sql.py", line 242, in __init__
    super().__init__(conn_id=conn_id, database=database, **kwargs)
  File "/home/airflow/.local/lib/python3.8/site-packages/airflow/models/baseoperator.py", line 437, in apply_defaults
    result = func(self, **kwargs, default_args=default_args)
  File "/home/airflow/.local/lib/python3.8/site-packages/airflow/providers/common/sql/operators/sql.py", line 139, in __init__
    super().__init__(**kwargs)
  File "/home/airflow/.local/lib/python3.8/site-packages/airflow/models/baseoperator.py", line 437, in apply_defaults
    result = func(self, **kwargs, default_args=default_args)
  File "/home/airflow/.local/lib/python3.8/site-packages/airflow/models/baseoperator.py", line 798, in __init__
    raise AirflowException(
airflow.exceptions.AirflowException: Invalid arguments were passed to PostgresOperator (task_id: create_postgres_table). Invalid arguments were:
**kwargs: {'postgres_connn_id': 'postgres_localhost'}
[2023-12-21T18:10:12.404+0000] {processor.py:842} WARNING - No viable dags retrieved from /opt/airflow/dags/dag_with_postgres_operator.py
[2023-12-21T18:10:12.468+0000] {processor.py:183} INFO - Processing /opt/airflow/dags/dag_with_postgres_operator.py took 0.133 seconds
[2023-12-21T18:10:43.129+0000] {processor.py:161} INFO - Started process (PID=4114) to work on /opt/airflow/dags/dag_with_postgres_operator.py
[2023-12-21T18:10:43.132+0000] {processor.py:830} INFO - Processing file /opt/airflow/dags/dag_with_postgres_operator.py for tasks to queue
[2023-12-21T18:10:43.135+0000] {logging_mixin.py:188} INFO - [2023-12-21T18:10:43.134+0000] {dagbag.py:538} INFO - Filling up the DagBag from /opt/airflow/dags/dag_with_postgres_operator.py
[2023-12-21T18:10:43.165+0000] {logging_mixin.py:188} INFO - [2023-12-21T18:10:43.156+0000] {dagbag.py:348} ERROR - Failed to import: /opt/airflow/dags/dag_with_postgres_operator.py
Traceback (most recent call last):
  File "/home/airflow/.local/lib/python3.8/site-packages/airflow/models/dagbag.py", line 344, in parse
    loader.exec_module(new_module)
  File "<frozen importlib._bootstrap_external>", line 843, in exec_module
  File "<frozen importlib._bootstrap>", line 219, in _call_with_frames_removed
  File "/opt/airflow/dags/dag_with_postgres_operator.py", line 20, in <module>
    task1 = PostgresOperator(
  File "/home/airflow/.local/lib/python3.8/site-packages/airflow/models/baseoperator.py", line 437, in apply_defaults
    result = func(self, **kwargs, default_args=default_args)
  File "/home/airflow/.local/lib/python3.8/site-packages/airflow/providers/postgres/operators/postgres.py", line 75, in __init__
    super().__init__(conn_id=postgres_conn_id, **kwargs)
  File "/home/airflow/.local/lib/python3.8/site-packages/airflow/models/baseoperator.py", line 437, in apply_defaults
    result = func(self, **kwargs, default_args=default_args)
  File "/home/airflow/.local/lib/python3.8/site-packages/airflow/providers/common/sql/operators/sql.py", line 242, in __init__
    super().__init__(conn_id=conn_id, database=database, **kwargs)
  File "/home/airflow/.local/lib/python3.8/site-packages/airflow/models/baseoperator.py", line 437, in apply_defaults
    result = func(self, **kwargs, default_args=default_args)
  File "/home/airflow/.local/lib/python3.8/site-packages/airflow/providers/common/sql/operators/sql.py", line 139, in __init__
    super().__init__(**kwargs)
  File "/home/airflow/.local/lib/python3.8/site-packages/airflow/models/baseoperator.py", line 437, in apply_defaults
    result = func(self, **kwargs, default_args=default_args)
  File "/home/airflow/.local/lib/python3.8/site-packages/airflow/models/baseoperator.py", line 798, in __init__
    raise AirflowException(
airflow.exceptions.AirflowException: Invalid arguments were passed to PostgresOperator (task_id: create_postgres_table). Invalid arguments were:
**kwargs: {'postgres_connn_id': 'postgres_localhost'}
[2023-12-21T18:10:43.169+0000] {processor.py:842} WARNING - No viable dags retrieved from /opt/airflow/dags/dag_with_postgres_operator.py
[2023-12-21T18:10:43.215+0000] {processor.py:183} INFO - Processing /opt/airflow/dags/dag_with_postgres_operator.py took 0.092 seconds
[2023-12-21T18:11:13.561+0000] {processor.py:161} INFO - Started process (PID=4150) to work on /opt/airflow/dags/dag_with_postgres_operator.py
[2023-12-21T18:11:13.564+0000] {processor.py:830} INFO - Processing file /opt/airflow/dags/dag_with_postgres_operator.py for tasks to queue
[2023-12-21T18:11:13.574+0000] {logging_mixin.py:188} INFO - [2023-12-21T18:11:13.572+0000] {dagbag.py:538} INFO - Filling up the DagBag from /opt/airflow/dags/dag_with_postgres_operator.py
[2023-12-21T18:11:13.605+0000] {logging_mixin.py:188} INFO - [2023-12-21T18:11:13.597+0000] {dagbag.py:348} ERROR - Failed to import: /opt/airflow/dags/dag_with_postgres_operator.py
Traceback (most recent call last):
  File "/home/airflow/.local/lib/python3.8/site-packages/airflow/models/dagbag.py", line 344, in parse
    loader.exec_module(new_module)
  File "<frozen importlib._bootstrap_external>", line 843, in exec_module
  File "<frozen importlib._bootstrap>", line 219, in _call_with_frames_removed
  File "/opt/airflow/dags/dag_with_postgres_operator.py", line 20, in <module>
    task1 = PostgresOperator(
  File "/home/airflow/.local/lib/python3.8/site-packages/airflow/models/baseoperator.py", line 437, in apply_defaults
    result = func(self, **kwargs, default_args=default_args)
  File "/home/airflow/.local/lib/python3.8/site-packages/airflow/providers/postgres/operators/postgres.py", line 75, in __init__
    super().__init__(conn_id=postgres_conn_id, **kwargs)
  File "/home/airflow/.local/lib/python3.8/site-packages/airflow/models/baseoperator.py", line 437, in apply_defaults
    result = func(self, **kwargs, default_args=default_args)
  File "/home/airflow/.local/lib/python3.8/site-packages/airflow/providers/common/sql/operators/sql.py", line 242, in __init__
    super().__init__(conn_id=conn_id, database=database, **kwargs)
  File "/home/airflow/.local/lib/python3.8/site-packages/airflow/models/baseoperator.py", line 437, in apply_defaults
    result = func(self, **kwargs, default_args=default_args)
  File "/home/airflow/.local/lib/python3.8/site-packages/airflow/providers/common/sql/operators/sql.py", line 139, in __init__
    super().__init__(**kwargs)
  File "/home/airflow/.local/lib/python3.8/site-packages/airflow/models/baseoperator.py", line 437, in apply_defaults
    result = func(self, **kwargs, default_args=default_args)
  File "/home/airflow/.local/lib/python3.8/site-packages/airflow/models/baseoperator.py", line 798, in __init__
    raise AirflowException(
airflow.exceptions.AirflowException: Invalid arguments were passed to PostgresOperator (task_id: create_postgres_table). Invalid arguments were:
**kwargs: {'postgres_connn_id': 'postgres_localhost'}
[2023-12-21T18:11:13.609+0000] {processor.py:842} WARNING - No viable dags retrieved from /opt/airflow/dags/dag_with_postgres_operator.py
[2023-12-21T18:11:13.667+0000] {processor.py:183} INFO - Processing /opt/airflow/dags/dag_with_postgres_operator.py took 0.117 seconds
[2023-12-21T18:11:44.024+0000] {processor.py:161} INFO - Started process (PID=4189) to work on /opt/airflow/dags/dag_with_postgres_operator.py
[2023-12-21T18:11:44.029+0000] {processor.py:830} INFO - Processing file /opt/airflow/dags/dag_with_postgres_operator.py for tasks to queue
[2023-12-21T18:11:44.032+0000] {logging_mixin.py:188} INFO - [2023-12-21T18:11:44.032+0000] {dagbag.py:538} INFO - Filling up the DagBag from /opt/airflow/dags/dag_with_postgres_operator.py
[2023-12-21T18:11:44.090+0000] {logging_mixin.py:188} INFO - [2023-12-21T18:11:44.077+0000] {dagbag.py:348} ERROR - Failed to import: /opt/airflow/dags/dag_with_postgres_operator.py
Traceback (most recent call last):
  File "/home/airflow/.local/lib/python3.8/site-packages/airflow/models/dagbag.py", line 344, in parse
    loader.exec_module(new_module)
  File "<frozen importlib._bootstrap_external>", line 843, in exec_module
  File "<frozen importlib._bootstrap>", line 219, in _call_with_frames_removed
  File "/opt/airflow/dags/dag_with_postgres_operator.py", line 20, in <module>
    task1 = PostgresOperator(
  File "/home/airflow/.local/lib/python3.8/site-packages/airflow/models/baseoperator.py", line 437, in apply_defaults
    result = func(self, **kwargs, default_args=default_args)
  File "/home/airflow/.local/lib/python3.8/site-packages/airflow/providers/postgres/operators/postgres.py", line 75, in __init__
    super().__init__(conn_id=postgres_conn_id, **kwargs)
  File "/home/airflow/.local/lib/python3.8/site-packages/airflow/models/baseoperator.py", line 437, in apply_defaults
    result = func(self, **kwargs, default_args=default_args)
  File "/home/airflow/.local/lib/python3.8/site-packages/airflow/providers/common/sql/operators/sql.py", line 242, in __init__
    super().__init__(conn_id=conn_id, database=database, **kwargs)
  File "/home/airflow/.local/lib/python3.8/site-packages/airflow/models/baseoperator.py", line 437, in apply_defaults
    result = func(self, **kwargs, default_args=default_args)
  File "/home/airflow/.local/lib/python3.8/site-packages/airflow/providers/common/sql/operators/sql.py", line 139, in __init__
    super().__init__(**kwargs)
  File "/home/airflow/.local/lib/python3.8/site-packages/airflow/models/baseoperator.py", line 437, in apply_defaults
    result = func(self, **kwargs, default_args=default_args)
  File "/home/airflow/.local/lib/python3.8/site-packages/airflow/models/baseoperator.py", line 798, in __init__
    raise AirflowException(
airflow.exceptions.AirflowException: Invalid arguments were passed to PostgresOperator (task_id: create_postgres_table). Invalid arguments were:
**kwargs: {'postgres_connn_id': 'postgres_localhost'}
[2023-12-21T18:11:44.095+0000] {processor.py:842} WARNING - No viable dags retrieved from /opt/airflow/dags/dag_with_postgres_operator.py
[2023-12-21T18:11:44.158+0000] {processor.py:183} INFO - Processing /opt/airflow/dags/dag_with_postgres_operator.py took 0.148 seconds
[2023-12-21T18:12:14.283+0000] {processor.py:161} INFO - Started process (PID=4226) to work on /opt/airflow/dags/dag_with_postgres_operator.py
[2023-12-21T18:12:14.289+0000] {processor.py:830} INFO - Processing file /opt/airflow/dags/dag_with_postgres_operator.py for tasks to queue
[2023-12-21T18:12:14.292+0000] {logging_mixin.py:188} INFO - [2023-12-21T18:12:14.291+0000] {dagbag.py:538} INFO - Filling up the DagBag from /opt/airflow/dags/dag_with_postgres_operator.py
[2023-12-21T18:12:14.326+0000] {logging_mixin.py:188} INFO - [2023-12-21T18:12:14.320+0000] {dagbag.py:348} ERROR - Failed to import: /opt/airflow/dags/dag_with_postgres_operator.py
Traceback (most recent call last):
  File "/home/airflow/.local/lib/python3.8/site-packages/airflow/models/dagbag.py", line 344, in parse
    loader.exec_module(new_module)
  File "<frozen importlib._bootstrap_external>", line 843, in exec_module
  File "<frozen importlib._bootstrap>", line 219, in _call_with_frames_removed
  File "/opt/airflow/dags/dag_with_postgres_operator.py", line 20, in <module>
    task1 = PostgresOperator(
  File "/home/airflow/.local/lib/python3.8/site-packages/airflow/models/baseoperator.py", line 437, in apply_defaults
    result = func(self, **kwargs, default_args=default_args)
  File "/home/airflow/.local/lib/python3.8/site-packages/airflow/providers/postgres/operators/postgres.py", line 75, in __init__
    super().__init__(conn_id=postgres_conn_id, **kwargs)
  File "/home/airflow/.local/lib/python3.8/site-packages/airflow/models/baseoperator.py", line 437, in apply_defaults
    result = func(self, **kwargs, default_args=default_args)
  File "/home/airflow/.local/lib/python3.8/site-packages/airflow/providers/common/sql/operators/sql.py", line 242, in __init__
    super().__init__(conn_id=conn_id, database=database, **kwargs)
  File "/home/airflow/.local/lib/python3.8/site-packages/airflow/models/baseoperator.py", line 437, in apply_defaults
    result = func(self, **kwargs, default_args=default_args)
  File "/home/airflow/.local/lib/python3.8/site-packages/airflow/providers/common/sql/operators/sql.py", line 139, in __init__
    super().__init__(**kwargs)
  File "/home/airflow/.local/lib/python3.8/site-packages/airflow/models/baseoperator.py", line 437, in apply_defaults
    result = func(self, **kwargs, default_args=default_args)
  File "/home/airflow/.local/lib/python3.8/site-packages/airflow/models/baseoperator.py", line 798, in __init__
    raise AirflowException(
airflow.exceptions.AirflowException: Invalid arguments were passed to PostgresOperator (task_id: create_postgres_table). Invalid arguments were:
**kwargs: {'postgres_connn_id': 'postgres_localhost'}
[2023-12-21T18:12:14.328+0000] {processor.py:842} WARNING - No viable dags retrieved from /opt/airflow/dags/dag_with_postgres_operator.py
[2023-12-21T18:12:14.372+0000] {processor.py:183} INFO - Processing /opt/airflow/dags/dag_with_postgres_operator.py took 0.099 seconds
[2023-12-21T18:12:44.765+0000] {processor.py:161} INFO - Started process (PID=4261) to work on /opt/airflow/dags/dag_with_postgres_operator.py
[2023-12-21T18:12:44.771+0000] {processor.py:830} INFO - Processing file /opt/airflow/dags/dag_with_postgres_operator.py for tasks to queue
[2023-12-21T18:12:44.777+0000] {logging_mixin.py:188} INFO - [2023-12-21T18:12:44.775+0000] {dagbag.py:538} INFO - Filling up the DagBag from /opt/airflow/dags/dag_with_postgres_operator.py
[2023-12-21T18:12:44.832+0000] {logging_mixin.py:188} INFO - [2023-12-21T18:12:44.820+0000] {dagbag.py:348} ERROR - Failed to import: /opt/airflow/dags/dag_with_postgres_operator.py
Traceback (most recent call last):
  File "/home/airflow/.local/lib/python3.8/site-packages/airflow/models/dagbag.py", line 344, in parse
    loader.exec_module(new_module)
  File "<frozen importlib._bootstrap_external>", line 843, in exec_module
  File "<frozen importlib._bootstrap>", line 219, in _call_with_frames_removed
  File "/opt/airflow/dags/dag_with_postgres_operator.py", line 20, in <module>
    task1 = PostgresOperator(
  File "/home/airflow/.local/lib/python3.8/site-packages/airflow/models/baseoperator.py", line 437, in apply_defaults
    result = func(self, **kwargs, default_args=default_args)
  File "/home/airflow/.local/lib/python3.8/site-packages/airflow/providers/postgres/operators/postgres.py", line 75, in __init__
    super().__init__(conn_id=postgres_conn_id, **kwargs)
  File "/home/airflow/.local/lib/python3.8/site-packages/airflow/models/baseoperator.py", line 437, in apply_defaults
    result = func(self, **kwargs, default_args=default_args)
  File "/home/airflow/.local/lib/python3.8/site-packages/airflow/providers/common/sql/operators/sql.py", line 242, in __init__
    super().__init__(conn_id=conn_id, database=database, **kwargs)
  File "/home/airflow/.local/lib/python3.8/site-packages/airflow/models/baseoperator.py", line 437, in apply_defaults
    result = func(self, **kwargs, default_args=default_args)
  File "/home/airflow/.local/lib/python3.8/site-packages/airflow/providers/common/sql/operators/sql.py", line 139, in __init__
    super().__init__(**kwargs)
  File "/home/airflow/.local/lib/python3.8/site-packages/airflow/models/baseoperator.py", line 437, in apply_defaults
    result = func(self, **kwargs, default_args=default_args)
  File "/home/airflow/.local/lib/python3.8/site-packages/airflow/models/baseoperator.py", line 798, in __init__
    raise AirflowException(
airflow.exceptions.AirflowException: Invalid arguments were passed to PostgresOperator (task_id: create_postgres_table). Invalid arguments were:
**kwargs: {'postgres_connn_id': 'postgres_localhost'}
[2023-12-21T18:12:44.836+0000] {processor.py:842} WARNING - No viable dags retrieved from /opt/airflow/dags/dag_with_postgres_operator.py
[2023-12-21T18:12:44.902+0000] {processor.py:183} INFO - Processing /opt/airflow/dags/dag_with_postgres_operator.py took 0.149 seconds
[2023-12-21T18:13:12.147+0000] {processor.py:161} INFO - Started process (PID=4291) to work on /opt/airflow/dags/dag_with_postgres_operator.py
[2023-12-21T18:13:12.153+0000] {processor.py:830} INFO - Processing file /opt/airflow/dags/dag_with_postgres_operator.py for tasks to queue
[2023-12-21T18:13:12.159+0000] {logging_mixin.py:188} INFO - [2023-12-21T18:13:12.157+0000] {dagbag.py:538} INFO - Filling up the DagBag from /opt/airflow/dags/dag_with_postgres_operator.py
[2023-12-21T18:13:12.213+0000] {logging_mixin.py:188} INFO - [2023-12-21T18:13:12.205+0000] {dagbag.py:348} ERROR - Failed to import: /opt/airflow/dags/dag_with_postgres_operator.py
Traceback (most recent call last):
  File "/home/airflow/.local/lib/python3.8/site-packages/airflow/models/dagbag.py", line 344, in parse
    loader.exec_module(new_module)
  File "<frozen importlib._bootstrap_external>", line 843, in exec_module
  File "<frozen importlib._bootstrap>", line 219, in _call_with_frames_removed
  File "/opt/airflow/dags/dag_with_postgres_operator.py", line 20, in <module>
    task1 = PostgresOperator(
  File "/home/airflow/.local/lib/python3.8/site-packages/airflow/models/baseoperator.py", line 437, in apply_defaults
    result = func(self, **kwargs, default_args=default_args)
  File "/home/airflow/.local/lib/python3.8/site-packages/airflow/providers/postgres/operators/postgres.py", line 75, in __init__
    super().__init__(conn_id=postgres_conn_id, **kwargs)
  File "/home/airflow/.local/lib/python3.8/site-packages/airflow/models/baseoperator.py", line 437, in apply_defaults
    result = func(self, **kwargs, default_args=default_args)
  File "/home/airflow/.local/lib/python3.8/site-packages/airflow/providers/common/sql/operators/sql.py", line 242, in __init__
    super().__init__(conn_id=conn_id, database=database, **kwargs)
  File "/home/airflow/.local/lib/python3.8/site-packages/airflow/models/baseoperator.py", line 437, in apply_defaults
    result = func(self, **kwargs, default_args=default_args)
  File "/home/airflow/.local/lib/python3.8/site-packages/airflow/providers/common/sql/operators/sql.py", line 139, in __init__
    super().__init__(**kwargs)
  File "/home/airflow/.local/lib/python3.8/site-packages/airflow/models/baseoperator.py", line 437, in apply_defaults
    result = func(self, **kwargs, default_args=default_args)
  File "/home/airflow/.local/lib/python3.8/site-packages/airflow/models/baseoperator.py", line 798, in __init__
    raise AirflowException(
airflow.exceptions.AirflowException: Invalid arguments were passed to PostgresOperator (task_id: create_postgres_table). Invalid arguments were:
**kwargs: {'postgres_connn_id': 'postgres_localhost'}
[2023-12-21T18:13:12.216+0000] {processor.py:842} WARNING - No viable dags retrieved from /opt/airflow/dags/dag_with_postgres_operator.py
[2023-12-21T18:13:12.261+0000] {processor.py:183} INFO - Processing /opt/airflow/dags/dag_with_postgres_operator.py took 0.120 seconds
[2023-12-21T18:13:42.492+0000] {processor.py:161} INFO - Started process (PID=4327) to work on /opt/airflow/dags/dag_with_postgres_operator.py
[2023-12-21T18:13:42.494+0000] {processor.py:830} INFO - Processing file /opt/airflow/dags/dag_with_postgres_operator.py for tasks to queue
[2023-12-21T18:13:42.498+0000] {logging_mixin.py:188} INFO - [2023-12-21T18:13:42.497+0000] {dagbag.py:538} INFO - Filling up the DagBag from /opt/airflow/dags/dag_with_postgres_operator.py
[2023-12-21T18:13:42.543+0000] {logging_mixin.py:188} INFO - [2023-12-21T18:13:42.532+0000] {dagbag.py:348} ERROR - Failed to import: /opt/airflow/dags/dag_with_postgres_operator.py
Traceback (most recent call last):
  File "/home/airflow/.local/lib/python3.8/site-packages/airflow/models/dagbag.py", line 344, in parse
    loader.exec_module(new_module)
  File "<frozen importlib._bootstrap_external>", line 843, in exec_module
  File "<frozen importlib._bootstrap>", line 219, in _call_with_frames_removed
  File "/opt/airflow/dags/dag_with_postgres_operator.py", line 20, in <module>
    task1 = PostgresOperator(
  File "/home/airflow/.local/lib/python3.8/site-packages/airflow/models/baseoperator.py", line 437, in apply_defaults
    result = func(self, **kwargs, default_args=default_args)
  File "/home/airflow/.local/lib/python3.8/site-packages/airflow/providers/postgres/operators/postgres.py", line 75, in __init__
    super().__init__(conn_id=postgres_conn_id, **kwargs)
  File "/home/airflow/.local/lib/python3.8/site-packages/airflow/models/baseoperator.py", line 437, in apply_defaults
    result = func(self, **kwargs, default_args=default_args)
  File "/home/airflow/.local/lib/python3.8/site-packages/airflow/providers/common/sql/operators/sql.py", line 242, in __init__
    super().__init__(conn_id=conn_id, database=database, **kwargs)
  File "/home/airflow/.local/lib/python3.8/site-packages/airflow/models/baseoperator.py", line 437, in apply_defaults
    result = func(self, **kwargs, default_args=default_args)
  File "/home/airflow/.local/lib/python3.8/site-packages/airflow/providers/common/sql/operators/sql.py", line 139, in __init__
    super().__init__(**kwargs)
  File "/home/airflow/.local/lib/python3.8/site-packages/airflow/models/baseoperator.py", line 437, in apply_defaults
    result = func(self, **kwargs, default_args=default_args)
  File "/home/airflow/.local/lib/python3.8/site-packages/airflow/models/baseoperator.py", line 798, in __init__
    raise AirflowException(
airflow.exceptions.AirflowException: Invalid arguments were passed to PostgresOperator (task_id: create_postgres_table). Invalid arguments were:
**kwargs: {'postgres_connn_id': 'postgres_localhost'}
[2023-12-21T18:13:42.548+0000] {processor.py:842} WARNING - No viable dags retrieved from /opt/airflow/dags/dag_with_postgres_operator.py
[2023-12-21T18:13:42.585+0000] {processor.py:183} INFO - Processing /opt/airflow/dags/dag_with_postgres_operator.py took 0.099 seconds
[2023-12-21T18:14:12.966+0000] {processor.py:161} INFO - Started process (PID=4364) to work on /opt/airflow/dags/dag_with_postgres_operator.py
[2023-12-21T18:14:12.972+0000] {processor.py:830} INFO - Processing file /opt/airflow/dags/dag_with_postgres_operator.py for tasks to queue
[2023-12-21T18:14:12.976+0000] {logging_mixin.py:188} INFO - [2023-12-21T18:14:12.975+0000] {dagbag.py:538} INFO - Filling up the DagBag from /opt/airflow/dags/dag_with_postgres_operator.py
[2023-12-21T18:14:13.045+0000] {logging_mixin.py:188} INFO - [2023-12-21T18:14:13.032+0000] {dagbag.py:348} ERROR - Failed to import: /opt/airflow/dags/dag_with_postgres_operator.py
Traceback (most recent call last):
  File "/home/airflow/.local/lib/python3.8/site-packages/airflow/models/dagbag.py", line 344, in parse
    loader.exec_module(new_module)
  File "<frozen importlib._bootstrap_external>", line 843, in exec_module
  File "<frozen importlib._bootstrap>", line 219, in _call_with_frames_removed
  File "/opt/airflow/dags/dag_with_postgres_operator.py", line 20, in <module>
    task1 = PostgresOperator(
  File "/home/airflow/.local/lib/python3.8/site-packages/airflow/models/baseoperator.py", line 437, in apply_defaults
    result = func(self, **kwargs, default_args=default_args)
  File "/home/airflow/.local/lib/python3.8/site-packages/airflow/providers/postgres/operators/postgres.py", line 75, in __init__
    super().__init__(conn_id=postgres_conn_id, **kwargs)
  File "/home/airflow/.local/lib/python3.8/site-packages/airflow/models/baseoperator.py", line 437, in apply_defaults
    result = func(self, **kwargs, default_args=default_args)
  File "/home/airflow/.local/lib/python3.8/site-packages/airflow/providers/common/sql/operators/sql.py", line 242, in __init__
    super().__init__(conn_id=conn_id, database=database, **kwargs)
  File "/home/airflow/.local/lib/python3.8/site-packages/airflow/models/baseoperator.py", line 437, in apply_defaults
    result = func(self, **kwargs, default_args=default_args)
  File "/home/airflow/.local/lib/python3.8/site-packages/airflow/providers/common/sql/operators/sql.py", line 139, in __init__
    super().__init__(**kwargs)
  File "/home/airflow/.local/lib/python3.8/site-packages/airflow/models/baseoperator.py", line 437, in apply_defaults
    result = func(self, **kwargs, default_args=default_args)
  File "/home/airflow/.local/lib/python3.8/site-packages/airflow/models/baseoperator.py", line 798, in __init__
    raise AirflowException(
airflow.exceptions.AirflowException: Invalid arguments were passed to PostgresOperator (task_id: create_postgres_table). Invalid arguments were:
**kwargs: {'postgres_connn_id': 'postgres_localhost'}
[2023-12-21T18:14:13.049+0000] {processor.py:842} WARNING - No viable dags retrieved from /opt/airflow/dags/dag_with_postgres_operator.py
[2023-12-21T18:14:13.169+0000] {processor.py:183} INFO - Processing /opt/airflow/dags/dag_with_postgres_operator.py took 0.218 seconds
[2023-12-21T18:14:43.313+0000] {processor.py:161} INFO - Started process (PID=4407) to work on /opt/airflow/dags/dag_with_postgres_operator.py
[2023-12-21T18:14:43.317+0000] {processor.py:830} INFO - Processing file /opt/airflow/dags/dag_with_postgres_operator.py for tasks to queue
[2023-12-21T18:14:43.325+0000] {logging_mixin.py:188} INFO - [2023-12-21T18:14:43.323+0000] {dagbag.py:538} INFO - Filling up the DagBag from /opt/airflow/dags/dag_with_postgres_operator.py
[2023-12-21T18:14:43.351+0000] {logging_mixin.py:188} INFO - [2023-12-21T18:14:43.346+0000] {dagbag.py:348} ERROR - Failed to import: /opt/airflow/dags/dag_with_postgres_operator.py
Traceback (most recent call last):
  File "/home/airflow/.local/lib/python3.8/site-packages/airflow/models/dagbag.py", line 344, in parse
    loader.exec_module(new_module)
  File "<frozen importlib._bootstrap_external>", line 843, in exec_module
  File "<frozen importlib._bootstrap>", line 219, in _call_with_frames_removed
  File "/opt/airflow/dags/dag_with_postgres_operator.py", line 20, in <module>
    task1 = PostgresOperator(
  File "/home/airflow/.local/lib/python3.8/site-packages/airflow/models/baseoperator.py", line 437, in apply_defaults
    result = func(self, **kwargs, default_args=default_args)
  File "/home/airflow/.local/lib/python3.8/site-packages/airflow/providers/postgres/operators/postgres.py", line 75, in __init__
    super().__init__(conn_id=postgres_conn_id, **kwargs)
  File "/home/airflow/.local/lib/python3.8/site-packages/airflow/models/baseoperator.py", line 437, in apply_defaults
    result = func(self, **kwargs, default_args=default_args)
  File "/home/airflow/.local/lib/python3.8/site-packages/airflow/providers/common/sql/operators/sql.py", line 242, in __init__
    super().__init__(conn_id=conn_id, database=database, **kwargs)
  File "/home/airflow/.local/lib/python3.8/site-packages/airflow/models/baseoperator.py", line 437, in apply_defaults
    result = func(self, **kwargs, default_args=default_args)
  File "/home/airflow/.local/lib/python3.8/site-packages/airflow/providers/common/sql/operators/sql.py", line 139, in __init__
    super().__init__(**kwargs)
  File "/home/airflow/.local/lib/python3.8/site-packages/airflow/models/baseoperator.py", line 437, in apply_defaults
    result = func(self, **kwargs, default_args=default_args)
  File "/home/airflow/.local/lib/python3.8/site-packages/airflow/models/baseoperator.py", line 798, in __init__
    raise AirflowException(
airflow.exceptions.AirflowException: Invalid arguments were passed to PostgresOperator (task_id: create_postgres_table). Invalid arguments were:
**kwargs: {'postgres_connn_id': 'postgres_localhost'}
[2023-12-21T18:14:43.362+0000] {processor.py:842} WARNING - No viable dags retrieved from /opt/airflow/dags/dag_with_postgres_operator.py
[2023-12-21T18:14:43.407+0000] {processor.py:183} INFO - Processing /opt/airflow/dags/dag_with_postgres_operator.py took 0.105 seconds
[2023-12-21T18:15:17.029+0000] {processor.py:161} INFO - Started process (PID=4437) to work on /opt/airflow/dags/dag_with_postgres_operator.py
[2023-12-21T18:15:17.057+0000] {processor.py:830} INFO - Processing file /opt/airflow/dags/dag_with_postgres_operator.py for tasks to queue
[2023-12-21T18:15:17.104+0000] {logging_mixin.py:188} INFO - [2023-12-21T18:15:17.085+0000] {dagbag.py:538} INFO - Filling up the DagBag from /opt/airflow/dags/dag_with_postgres_operator.py
[2023-12-21T18:15:17.405+0000] {logging_mixin.py:188} INFO - [2023-12-21T18:15:17.377+0000] {dagbag.py:348} ERROR - Failed to import: /opt/airflow/dags/dag_with_postgres_operator.py
Traceback (most recent call last):
  File "/home/airflow/.local/lib/python3.8/site-packages/airflow/models/dagbag.py", line 344, in parse
    loader.exec_module(new_module)
  File "<frozen importlib._bootstrap_external>", line 843, in exec_module
  File "<frozen importlib._bootstrap>", line 219, in _call_with_frames_removed
  File "/opt/airflow/dags/dag_with_postgres_operator.py", line 20, in <module>
    task1 = PostgresOperator(
  File "/home/airflow/.local/lib/python3.8/site-packages/airflow/models/baseoperator.py", line 437, in apply_defaults
    result = func(self, **kwargs, default_args=default_args)
  File "/home/airflow/.local/lib/python3.8/site-packages/airflow/providers/postgres/operators/postgres.py", line 75, in __init__
    super().__init__(conn_id=postgres_conn_id, **kwargs)
  File "/home/airflow/.local/lib/python3.8/site-packages/airflow/models/baseoperator.py", line 437, in apply_defaults
    result = func(self, **kwargs, default_args=default_args)
  File "/home/airflow/.local/lib/python3.8/site-packages/airflow/providers/common/sql/operators/sql.py", line 242, in __init__
    super().__init__(conn_id=conn_id, database=database, **kwargs)
  File "/home/airflow/.local/lib/python3.8/site-packages/airflow/models/baseoperator.py", line 437, in apply_defaults
    result = func(self, **kwargs, default_args=default_args)
  File "/home/airflow/.local/lib/python3.8/site-packages/airflow/providers/common/sql/operators/sql.py", line 139, in __init__
    super().__init__(**kwargs)
  File "/home/airflow/.local/lib/python3.8/site-packages/airflow/models/baseoperator.py", line 437, in apply_defaults
    result = func(self, **kwargs, default_args=default_args)
  File "/home/airflow/.local/lib/python3.8/site-packages/airflow/models/baseoperator.py", line 798, in __init__
    raise AirflowException(
airflow.exceptions.AirflowException: Invalid arguments were passed to PostgresOperator (task_id: create_postgres_table). Invalid arguments were:
**kwargs: {'postgres_connn_id': 'postgres_localhost'}
[2023-12-21T18:15:17.419+0000] {processor.py:842} WARNING - No viable dags retrieved from /opt/airflow/dags/dag_with_postgres_operator.py
[2023-12-21T18:15:17.543+0000] {processor.py:183} INFO - Processing /opt/airflow/dags/dag_with_postgres_operator.py took 1.379 seconds
[2023-12-21T21:04:18.419+0000] {processor.py:161} INFO - Started process (PID=4475) to work on /opt/airflow/dags/dag_with_postgres_operator.py
[2023-12-21T21:04:18.616+0000] {processor.py:830} INFO - Processing file /opt/airflow/dags/dag_with_postgres_operator.py for tasks to queue
[2023-12-21T21:04:18.731+0000] {logging_mixin.py:188} INFO - [2023-12-21T21:04:18.728+0000] {dagbag.py:538} INFO - Filling up the DagBag from /opt/airflow/dags/dag_with_postgres_operator.py
[2023-12-21T21:04:20.144+0000] {logging_mixin.py:188} INFO - [2023-12-21T21:04:20.027+0000] {dagbag.py:348} ERROR - Failed to import: /opt/airflow/dags/dag_with_postgres_operator.py
Traceback (most recent call last):
  File "/home/airflow/.local/lib/python3.8/site-packages/airflow/models/dagbag.py", line 344, in parse
    loader.exec_module(new_module)
  File "<frozen importlib._bootstrap_external>", line 843, in exec_module
  File "<frozen importlib._bootstrap>", line 219, in _call_with_frames_removed
  File "/opt/airflow/dags/dag_with_postgres_operator.py", line 20, in <module>
    task1 = PostgresOperator(
  File "/home/airflow/.local/lib/python3.8/site-packages/airflow/models/baseoperator.py", line 437, in apply_defaults
    result = func(self, **kwargs, default_args=default_args)
  File "/home/airflow/.local/lib/python3.8/site-packages/airflow/providers/postgres/operators/postgres.py", line 75, in __init__
    super().__init__(conn_id=postgres_conn_id, **kwargs)
  File "/home/airflow/.local/lib/python3.8/site-packages/airflow/models/baseoperator.py", line 437, in apply_defaults
    result = func(self, **kwargs, default_args=default_args)
  File "/home/airflow/.local/lib/python3.8/site-packages/airflow/providers/common/sql/operators/sql.py", line 242, in __init__
    super().__init__(conn_id=conn_id, database=database, **kwargs)
  File "/home/airflow/.local/lib/python3.8/site-packages/airflow/models/baseoperator.py", line 437, in apply_defaults
    result = func(self, **kwargs, default_args=default_args)
  File "/home/airflow/.local/lib/python3.8/site-packages/airflow/providers/common/sql/operators/sql.py", line 139, in __init__
    super().__init__(**kwargs)
  File "/home/airflow/.local/lib/python3.8/site-packages/airflow/models/baseoperator.py", line 437, in apply_defaults
    result = func(self, **kwargs, default_args=default_args)
  File "/home/airflow/.local/lib/python3.8/site-packages/airflow/models/baseoperator.py", line 798, in __init__
    raise AirflowException(
airflow.exceptions.AirflowException: Invalid arguments were passed to PostgresOperator (task_id: create_postgres_table). Invalid arguments were:
**kwargs: {'postgres_connn_id': 'postgres_localhost'}
[2023-12-21T21:04:20.168+0000] {processor.py:842} WARNING - No viable dags retrieved from /opt/airflow/dags/dag_with_postgres_operator.py
[2023-12-21T21:04:20.570+0000] {processor.py:183} INFO - Processing /opt/airflow/dags/dag_with_postgres_operator.py took 3.848 seconds
