[2023-12-22T03:54:53.536+0000] {taskinstance.py:1957} INFO - Dependencies all met for dep_context=non-requeueable deps ti=<TaskInstance: dag_with_postgres_operator_v02.insert_into_postgres_table scheduled__2023-12-16T00:00:00+00:00 [queued]>
[2023-12-22T03:54:53.692+0000] {taskinstance.py:1957} INFO - Dependencies all met for dep_context=requeueable deps ti=<TaskInstance: dag_with_postgres_operator_v02.insert_into_postgres_table scheduled__2023-12-16T00:00:00+00:00 [queued]>
[2023-12-22T03:54:53.698+0000] {taskinstance.py:2171} INFO - Starting attempt 1 of 1
[2023-12-22T03:54:55.135+0000] {taskinstance.py:2192} INFO - Executing <Task(PostgresOperator): insert_into_postgres_table> on 2023-12-16 00:00:00+00:00
[2023-12-22T03:54:55.239+0000] {standard_task_runner.py:60} INFO - Started process 9379 to run task
[2023-12-22T03:54:55.323+0000] {standard_task_runner.py:87} INFO - Running: ['***', 'tasks', 'run', 'dag_with_postgres_operator_v02', 'insert_into_postgres_table', 'scheduled__2023-12-16T00:00:00+00:00', '--job-id', '114', '--raw', '--subdir', 'DAGS_FOLDER/dag_with_postgres_operator.py', '--cfg-path', '/tmp/tmpcg5ur16c']
[2023-12-22T03:54:55.437+0000] {standard_task_runner.py:88} INFO - Job 114: Subtask insert_into_postgres_table
[2023-12-22T03:54:55.977+0000] {task_command.py:423} INFO - Running <TaskInstance: dag_with_postgres_operator_v02.insert_into_postgres_table scheduled__2023-12-16T00:00:00+00:00 [running]> on host dd88aaafc1d9
[2023-12-22T03:54:56.558+0000] {taskinstance.py:2481} INFO - Exporting env vars: AIRFLOW_CTX_DAG_OWNER='sarwar' AIRFLOW_CTX_DAG_ID='dag_with_postgres_operator_v02' AIRFLOW_CTX_TASK_ID='insert_into_postgres_table' AIRFLOW_CTX_EXECUTION_DATE='2023-12-16T00:00:00+00:00' AIRFLOW_CTX_TRY_NUMBER='1' AIRFLOW_CTX_DAG_RUN_ID='scheduled__2023-12-16T00:00:00+00:00'
[2023-12-22T03:54:56.588+0000] {sql.py:276} INFO - Executing: 
            insert into dag_runs (dt, dag_id) values(<method 'date' of 'datetime.datetime' objects>, dag_with_postgres_operator_v02 )
        
[2023-12-22T03:54:56.693+0000] {base.py:83} INFO - Using connection ID 'postgres_localhost' for task execution.
[2023-12-22T03:54:56.724+0000] {base.py:83} INFO - Using connection ID 'postgres_localhost' for task execution.
[2023-12-22T03:54:56.785+0000] {sql.py:432} INFO - Running statement: 
            insert into dag_runs (dt, dag_id) values(<method 'date' of 'datetime.datetime' objects>, dag_with_postgres_operator_v02 )
        , parameters: None
[2023-12-22T03:54:56.813+0000] {taskinstance.py:2699} ERROR - Task failed with exception
Traceback (most recent call last):
  File "/home/airflow/.local/lib/python3.8/site-packages/airflow/models/taskinstance.py", line 433, in _execute_task
    result = execute_callable(context=context, **execute_callable_kwargs)
  File "/home/airflow/.local/lib/python3.8/site-packages/airflow/providers/common/sql/operators/sql.py", line 282, in execute
    output = hook.run(
  File "/home/airflow/.local/lib/python3.8/site-packages/airflow/providers/common/sql/hooks/sql.py", line 392, in run
    self._run_command(cur, sql_statement, parameters)
  File "/home/airflow/.local/lib/python3.8/site-packages/airflow/providers/common/sql/hooks/sql.py", line 437, in _run_command
    cur.execute(sql_statement)
psycopg2.errors.SyntaxError: syntax error at or near "<"
LINE 2: ...         insert into dag_runs (dt, dag_id) values(<method 'd...
                                                             ^

[2023-12-22T03:54:56.893+0000] {taskinstance.py:1138} INFO - Marking task as FAILED. dag_id=dag_with_postgres_operator_v02, task_id=insert_into_postgres_table, execution_date=20231216T000000, start_date=20231222T035453, end_date=20231222T035456
[2023-12-22T03:54:56.969+0000] {standard_task_runner.py:107} ERROR - Failed to execute job 114 for task insert_into_postgres_table (syntax error at or near "<"
LINE 2: ...         insert into dag_runs (dt, dag_id) values(<method 'd...
                                                             ^
; 9379)
[2023-12-22T03:54:57.094+0000] {local_task_job_runner.py:234} INFO - Task exited with return code 1
[2023-12-22T03:54:57.431+0000] {taskinstance.py:3281} INFO - 0 downstream tasks scheduled from follow-on schedule check
