[2023-12-22T14:53:53.226+0000] {taskinstance.py:1957} INFO - Dependencies all met for dep_context=non-requeueable deps ti=<TaskInstance: dag_with_postgres_hooks_v02.postgres_to_s3 manual__2023-12-22T14:53:46.853326+00:00 [queued]>
[2023-12-22T14:53:53.458+0000] {taskinstance.py:1957} INFO - Dependencies all met for dep_context=requeueable deps ti=<TaskInstance: dag_with_postgres_hooks_v02.postgres_to_s3 manual__2023-12-22T14:53:46.853326+00:00 [queued]>
[2023-12-22T14:53:53.462+0000] {taskinstance.py:2171} INFO - Starting attempt 1 of 1
[2023-12-22T14:53:53.671+0000] {taskinstance.py:2192} INFO - Executing <Task(PythonOperator): postgres_to_s3> on 2023-12-22 14:53:46.853326+00:00
[2023-12-22T14:53:53.689+0000] {standard_task_runner.py:60} INFO - Started process 58485 to run task
[2023-12-22T14:53:53.705+0000] {standard_task_runner.py:87} INFO - Running: ['***', 'tasks', 'run', 'dag_with_postgres_hooks_v02', 'postgres_to_s3', 'manual__2023-12-22T14:53:46.853326+00:00', '--job-id', '249', '--raw', '--subdir', 'DAGS_FOLDER/dag_with_postgres_hooks.py', '--cfg-path', '/tmp/tmp7ld60p1p']
[2023-12-22T14:53:53.734+0000] {standard_task_runner.py:88} INFO - Job 249: Subtask postgres_to_s3
[2023-12-22T14:53:54.047+0000] {task_command.py:423} INFO - Running <TaskInstance: dag_with_postgres_hooks_v02.postgres_to_s3 manual__2023-12-22T14:53:46.853326+00:00 [running]> on host dd88aaafc1d9
[2023-12-22T14:53:54.432+0000] {taskinstance.py:2481} INFO - Exporting env vars: AIRFLOW_CTX_DAG_OWNER='sarwar' AIRFLOW_CTX_DAG_ID='dag_with_postgres_hooks_v02' AIRFLOW_CTX_TASK_ID='postgres_to_s3' AIRFLOW_CTX_EXECUTION_DATE='2023-12-22T14:53:46.853326+00:00' AIRFLOW_CTX_TRY_NUMBER='1' AIRFLOW_CTX_DAG_RUN_ID='manual__2023-12-22T14:53:46.853326+00:00'
[2023-12-22T14:53:54.467+0000] {logging_mixin.py:188} WARNING - /home/***/.local/lib/python3.8/site-packages/***/utils/context.py:207 AirflowContextDeprecationWarning: Accessing 'next_ds_nodash' from the template is deprecated and will be removed in a future version. Please use '{{ data_interval_end | ds_nodash }}' instead.
[2023-12-22T14:53:54.493+0000] {base.py:83} INFO - Using connection ID 'postgres_localhost' for task execution.
[2023-12-22T14:53:54.523+0000] {taskinstance.py:2699} ERROR - Task failed with exception
Traceback (most recent call last):
  File "/home/airflow/.local/lib/python3.8/site-packages/airflow/models/taskinstance.py", line 433, in _execute_task
    result = execute_callable(context=context, **execute_callable_kwargs)
  File "/home/airflow/.local/lib/python3.8/site-packages/airflow/operators/python.py", line 199, in execute
    return_value = self.execute_callable()
  File "/home/airflow/.local/lib/python3.8/site-packages/airflow/operators/python.py", line 216, in execute_callable
    return self.python_callable(*self.op_args, **self.op_kwargs)
  File "/opt/airflow/dags/dag_with_postgres_hooks.py", line 19, in postgres_to_s3
    cursor.execute("select * from public.orders where date >= %s and date <= %s", ds_nodash, next_ds_nodash)
TypeError: function takes at most 2 arguments (3 given)
[2023-12-22T14:53:54.556+0000] {taskinstance.py:1138} INFO - Marking task as FAILED. dag_id=dag_with_postgres_hooks_v02, task_id=postgres_to_s3, execution_date=20231222T145346, start_date=20231222T145353, end_date=20231222T145354
[2023-12-22T14:53:54.608+0000] {standard_task_runner.py:107} ERROR - Failed to execute job 249 for task postgres_to_s3 (function takes at most 2 arguments (3 given); 58485)
[2023-12-22T14:53:54.726+0000] {local_task_job_runner.py:234} INFO - Task exited with return code 1
[2023-12-22T14:53:54.873+0000] {taskinstance.py:3281} INFO - 0 downstream tasks scheduled from follow-on schedule check
