[2023-12-22T03:31:48.878+0000] {taskinstance.py:1957} INFO - Dependencies all met for dep_context=non-requeueable deps ti=<TaskInstance: dag_with_postgres_operator_v01.create_postgres_table manual__2023-12-22T03:30:55.653073+00:00 [queued]>
[2023-12-22T03:31:48.899+0000] {taskinstance.py:1957} INFO - Dependencies all met for dep_context=requeueable deps ti=<TaskInstance: dag_with_postgres_operator_v01.create_postgres_table manual__2023-12-22T03:30:55.653073+00:00 [queued]>
[2023-12-22T03:31:48.902+0000] {taskinstance.py:2171} INFO - Starting attempt 2 of 2
[2023-12-22T03:31:48.934+0000] {taskinstance.py:2192} INFO - Executing <Task(PostgresOperator): create_postgres_table> on 2023-12-22 03:30:55.653073+00:00
[2023-12-22T03:31:48.943+0000] {standard_task_runner.py:60} INFO - Started process 7643 to run task
[2023-12-22T03:31:48.949+0000] {standard_task_runner.py:87} INFO - Running: ['***', 'tasks', 'run', 'dag_with_postgres_operator_v01', 'create_postgres_table', 'manual__2023-12-22T03:30:55.653073+00:00', '--job-id', '94', '--raw', '--subdir', 'DAGS_FOLDER/dag_with_postgres_operator.py', '--cfg-path', '/tmp/tmp0qe49m82']
[2023-12-22T03:31:48.956+0000] {standard_task_runner.py:88} INFO - Job 94: Subtask create_postgres_table
[2023-12-22T03:31:49.053+0000] {task_command.py:423} INFO - Running <TaskInstance: dag_with_postgres_operator_v01.create_postgres_table manual__2023-12-22T03:30:55.653073+00:00 [running]> on host dd88aaafc1d9
[2023-12-22T03:31:49.208+0000] {taskinstance.py:2481} INFO - Exporting env vars: AIRFLOW_CTX_DAG_OWNER='sarwar' AIRFLOW_CTX_DAG_ID='dag_with_postgres_operator_v01' AIRFLOW_CTX_TASK_ID='create_postgres_table' AIRFLOW_CTX_EXECUTION_DATE='2023-12-22T03:30:55.653073+00:00' AIRFLOW_CTX_TRY_NUMBER='2' AIRFLOW_CTX_DAG_RUN_ID='manual__2023-12-22T03:30:55.653073+00:00'
[2023-12-22T03:31:49.213+0000] {sql.py:276} INFO - Executing: 
        create table if not exists dag_runs (
        dt date,
        dag_id varchar,
        primary key(dt, dag_id)
        )
        
[2023-12-22T03:31:49.235+0000] {base.py:83} INFO - Using connection ID 'postgres_localhost' for task execution.
[2023-12-22T03:31:49.259+0000] {base.py:83} INFO - Using connection ID 'postgres_localhost' for task execution.
[2023-12-22T03:31:49.263+0000] {taskinstance.py:2699} ERROR - Task failed with exception
Traceback (most recent call last):
  File "/home/airflow/.local/lib/python3.8/site-packages/airflow/models/taskinstance.py", line 433, in _execute_task
    result = execute_callable(context=context, **execute_callable_kwargs)
  File "/home/airflow/.local/lib/python3.8/site-packages/airflow/providers/common/sql/operators/sql.py", line 282, in execute
    output = hook.run(
  File "/home/airflow/.local/lib/python3.8/site-packages/airflow/providers/common/sql/hooks/sql.py", line 385, in run
    with closing(self.get_conn()) as conn:
  File "/home/airflow/.local/lib/python3.8/site-packages/airflow/providers/postgres/hooks/postgres.py", line 158, in get_conn
    self.conn = psycopg2.connect(**conn_args)
  File "/home/airflow/.local/lib/python3.8/site-packages/psycopg2/__init__.py", line 122, in connect
    conn = _connect(dsn, connection_factory=connection_factory, **kwasync)
psycopg2.OperationalError: connection to server at "localhost" (127.0.0.1), port 5432 failed: Connection refused
	Is the server running on that host and accepting TCP/IP connections?
connection to server at "localhost" (::1), port 5432 failed: Cannot assign requested address
	Is the server running on that host and accepting TCP/IP connections?

[2023-12-22T03:31:49.287+0000] {taskinstance.py:1138} INFO - Marking task as FAILED. dag_id=dag_with_postgres_operator_v01, task_id=create_postgres_table, execution_date=20231222T033055, start_date=20231222T033148, end_date=20231222T033149
[2023-12-22T03:31:49.314+0000] {standard_task_runner.py:107} ERROR - Failed to execute job 94 for task create_postgres_table (connection to server at "localhost" (127.0.0.1), port 5432 failed: Connection refused
	Is the server running on that host and accepting TCP/IP connections?
connection to server at "localhost" (::1), port 5432 failed: Cannot assign requested address
	Is the server running on that host and accepting TCP/IP connections?
; 7643)
[2023-12-22T03:31:49.377+0000] {local_task_job_runner.py:234} INFO - Task exited with return code 1
[2023-12-22T03:31:49.415+0000] {taskinstance.py:3281} INFO - 0 downstream tasks scheduled from follow-on schedule check
