[2023-12-20T09:38:26.831+0000] {taskinstance.py:1957} INFO - Dependencies all met for dep_context=non-requeueable deps ti=<TaskInstance: our_dag_with_python_operator_v05.get_name manual__2023-12-20T09:38:22.988489+00:00 [queued]>
[2023-12-20T09:38:26.967+0000] {taskinstance.py:1957} INFO - Dependencies all met for dep_context=requeueable deps ti=<TaskInstance: our_dag_with_python_operator_v05.get_name manual__2023-12-20T09:38:22.988489+00:00 [queued]>
[2023-12-20T09:38:26.972+0000] {taskinstance.py:2171} INFO - Starting attempt 1 of 1
[2023-12-20T09:38:27.274+0000] {taskinstance.py:2192} INFO - Executing <Task(PythonOperator): get_name> on 2023-12-20 09:38:22.988489+00:00
[2023-12-20T09:38:27.303+0000] {standard_task_runner.py:60} INFO - Started process 8007 to run task
[2023-12-20T09:38:27.322+0000] {standard_task_runner.py:87} INFO - Running: ['***', 'tasks', 'run', 'our_dag_with_python_operator_v05', 'get_name', 'manual__2023-12-20T09:38:22.988489+00:00', '--job-id', '30', '--raw', '--subdir', 'DAGS_FOLDER/create_dag_with_python_operator.py', '--cfg-path', '/tmp/tmpnld_f0lf']
[2023-12-20T09:38:27.344+0000] {standard_task_runner.py:88} INFO - Job 30: Subtask get_name
[2023-12-20T09:38:27.520+0000] {task_command.py:423} INFO - Running <TaskInstance: our_dag_with_python_operator_v05.get_name manual__2023-12-20T09:38:22.988489+00:00 [running]> on host 5bd5db5a939a
[2023-12-20T09:38:27.720+0000] {taskinstance.py:2481} INFO - Exporting env vars: AIRFLOW_CTX_DAG_OWNER='sarwar' AIRFLOW_CTX_DAG_ID='our_dag_with_python_operator_v05' AIRFLOW_CTX_TASK_ID='get_name' AIRFLOW_CTX_EXECUTION_DATE='2023-12-20T09:38:22.988489+00:00' AIRFLOW_CTX_TRY_NUMBER='1' AIRFLOW_CTX_DAG_RUN_ID='manual__2023-12-20T09:38:22.988489+00:00'
[2023-12-20T09:38:27.727+0000] {taskinstance.py:2699} ERROR - Task failed with exception
Traceback (most recent call last):
  File "/home/airflow/.local/lib/python3.8/site-packages/airflow/models/taskinstance.py", line 433, in _execute_task
    result = execute_callable(context=context, **execute_callable_kwargs)
  File "/home/airflow/.local/lib/python3.8/site-packages/airflow/operators/python.py", line 199, in execute
    return_value = self.execute_callable()
  File "/home/airflow/.local/lib/python3.8/site-packages/airflow/operators/python.py", line 216, in execute_callable
    return self.python_callable(*self.op_args, **self.op_kwargs)
  File "/opt/airflow/dags/create_dag_with_python_operator.py", line 17, in get_name
    ti.xcom_pull(key='first_name', value='golam')
  File "/home/airflow/.local/lib/python3.8/site-packages/airflow/utils/session.py", line 79, in wrapper
    return func(*args, session=session, **kwargs)
TypeError: xcom_pull() got an unexpected keyword argument 'value'
[2023-12-20T09:38:27.764+0000] {taskinstance.py:1138} INFO - Marking task as FAILED. dag_id=our_dag_with_python_operator_v05, task_id=get_name, execution_date=20231220T093822, start_date=20231220T093826, end_date=20231220T093827
[2023-12-20T09:38:27.802+0000] {standard_task_runner.py:107} ERROR - Failed to execute job 30 for task get_name (xcom_pull() got an unexpected keyword argument 'value'; 8007)
[2023-12-20T09:38:27.862+0000] {local_task_job_runner.py:234} INFO - Task exited with return code 1
[2023-12-20T09:38:27.931+0000] {taskinstance.py:3281} INFO - 0 downstream tasks scheduled from follow-on schedule check
